Workbook

Sheet Board
E2: =E3-1 -> 46174 | F2: =F3-1 -> 46172 | H2: =H3 -> 46022
B3: 구 분 | D3: =+WORKDAY(TODAY(),-1) -> 46176 | E3: =D3-1 -> 46175 | F3: =E2-1 -> 46173 | G3: 전일대비 | H3: =DATE(YEAR(D3),MONTH(1),DAY(1)-1) -> 46022 | I3: YTD | M3: 인덱스명 | N3: Ticker | O3: 전담당 | P3: 변경요청 | Q3: 변경일자 | R3: 티커
B4: Spreads | C4: EM Spread | D4: =VLOOKUP(D$3,LAST!$B:$P,2,0) -> 215.27 | E4: =IF(VLOOKUP(E$3,LAST!$B:$P,2,0)=$D4,VLOOKUP(E$2,LAST!$B:$P,2,0),VLOOKUP(E$3,LAST!$B:$P,2,0)) -> 214.92 | F4: =IF(VLOOKUP(F$3,LAST!$B:$P,2,0)=$D4,VLOOKUP(F$2,LAST!$B:$P,2,0),VLOOKUP(F$3,LAST!$B:$P,2,0)) -> 214.56 | G4: =IF($D4-E4=0,$D4-F4,$D4-E4) -> 0.35 | H4: =IF(VLOOKUP(H$3,LAST!$B:$P,2,0)=$D4,VLOOKUP(H$2,LAST!$B:$P,2,0),VLOOKUP(H$3,LAST!$B:$P,2,0)) -> 231.44 | I4: =$D4-H4 -> -16.17 | M4: JPMorgan Monthly EMBIs | N4: JPEIGLSP Index | O4: 박성덕 선임
C5: Global HY Spread | D5: =VLOOKUP(D$3,LAST!$B:$P,3,0)*100 -> 275.4 | E5: =IF(VLOOKUP(E$3,LAST!$B:$P,3,0)*100=$D5,VLOOKUP(E$2,LAST!$B:$P,3,0)*100,VLOOKUP(E$3,LAST!$B:$P,3,0)*100) -> 273.33 | F5: =IF(VLOOKUP(F$3,LAST!$B:$P,3,0)*100=$D5,VLOOKUP(F$2,LAST!$B:$P,3,0)*100,VLOOKUP(F$3,LAST!$B:$P,3,0)*100) -> 277.42 | G5: =IF($D5-E5=0,$D5-F5,$D5-E5) -> 2.07 | H5: =IF(VLOOKUP(H$3,LAST!$B:$P,3,0)*100=$D5,VLOOKUP(H$2,LAST!$B:$P,3,0)*100,VLOOKUP(H$3,LAST!$B:$P,3,0)*100) -> 290.8 | I5: =$D5-H5 -> -15.4 | M5: BBG Global HY Avg OAS | N5: LG30OAS INDEX | O5: 박성덕 선임
C6: US HY Spread | D6: =VLOOKUP(D$3,LAST!$B:$Q,16,0)*100 -> 263 | E6: =IF(VLOOKUP(E$3,LAST!$B:$Q,16,0)*100=$D6,VLOOKUP(E$2,LAST!$B:$Q,16,0)*100,VLOOKUP(E$3,LAST!$B:$Q,16,0)*100) -> 257 | F6: =IF(VLOOKUP(F$3,LAST!$B:$Q,16,0)*100=$D6,VLOOKUP(F$2,LAST!$B:$Q,16,0)*100,VLOOKUP(F$2,LAST!$B:$Q,16,0)*100) -> 257 | G6: =IF($D6-E6=0,$D6-F6,$D6-E6) -> 6 | H6: =IF(VLOOKUP(H$3,LAST!$B:$Q,16,0)*100=$D6,VLOOKUP(H$2,LAST!$B:$Q,16,0)*100,VLOOKUP(H$3,LAST!$B:$Q,16,0)*100) -> 266 | I6: =$D6-H6 -> -3 | M6: BBG US Corporate High Yield (Index OAS to Treasury) | N6: LF98TRUU Index | O6: 신규 | P6: 김지호 매니저 | Q6: 45077 | R6: LF98OAS Index
C7: US Mid-IG Spread | D7: =VLOOKUP(D$3,LAST!$B:$Z,17,0)*100 -> 73 | E7: =IF(VLOOKUP(E$3,LAST!$B:$Z,17,0)*100=$D7,VLOOKUP(E$2,LAST!$B:$Z,17,0)*100,VLOOKUP(E$3,LAST!$B:$Z,17,0)*100) -> 72 | F7: =IF(VLOOKUP(F$3,LAST!$B:$Z,17,0)*100=$D7,VLOOKUP(F$2,LAST!$B:$Z,17,0)*100,VLOOKUP(F$2,LAST!$B:$Z,17,0)*100) -> 72 | G7: =IF($D7-E7=0,$D7-F7,$D7-E7) -> 1 | H7: =IF(VLOOKUP(H$3,LAST!$B:$Z,17,0)*100=$D7,VLOOKUP(H$2,LAST!$B:$Z,17,0)*100,VLOOKUP(H$3,LAST!$B:$Z,17,0)*100) -> 78 | I7: =$D7-H7 -> -5 | M7: Bloomberg US Agg Corporate Avg OAS | N7: LUACOAS Index | O7: 신규
C8: US Long-IG Spread | D8: =VLOOKUP(D$3,LAST!$B:$Z,18,0)*100 -> 88 | E8: =IF(VLOOKUP(E$3,LAST!$B:$Z,18,0)*100=$D8,VLOOKUP(E$2,LAST!$B:$Z,18,0)*100,VLOOKUP(E$3,LAST!$B:$Z,18,0)*100) -> 87 | F8: =IF(VLOOKUP(F$3,LAST!$B:$Z,18,0)*100=$D8,VLOOKUP(F$2,LAST!$B:$Z,18,0)*100,VLOOKUP(F$2,LAST!$B:$Z,18,0)*100) -> 87 | G8: =IF($D8-E8=0,$D8-F8,$D8-E8) -> 1 | H8: =IF(VLOOKUP(H$3,LAST!$B:$Z,18,0)*100=$D8,VLOOKUP(H$2,LAST!$B:$Z,18,0)*100,VLOOKUP(H$3,LAST!$B:$Z,18,0)*100) -> 94 | I8: =$D8-H8 -> -6 | M8: Bloomberg Long US Corporate Avg OAS | N8: LD07OAS Index | O8: 신규
C9: Muni OAS | D9: =VLOOKUP(D$3,LAST!$B:$Z,19,0)*100 -> 67 | E9: =IF(VLOOKUP(E$3,LAST!$B:$Z,19,0)*100=$D9,VLOOKUP(E$2,LAST!$B:$Z,19,0)*100,VLOOKUP(E$3,LAST!$B:$Z,19,0)*100) -> 68 | F9: =IF(VLOOKUP(F$3,LAST!$B:$Z,19,0)*100=$D9,VLOOKUP(F$2,LAST!$B:$Z,19,0)*100,VLOOKUP(F$2,LAST!$B:$Z,19,0)*100) -> 69 | G9: =IF($D9-E9=0,$D9-F9,$D9-E9) -> -1 | H9: =IF(VLOOKUP(H$3,LAST!$B:$Z,19,0)*100=$D9,VLOOKUP(H$2,LAST!$B:$Z,19,0)*100,VLOOKUP(H$3,LAST!$B:$Z,19,0)*100) -> 73 | I9: =$D9-H9 -> -6 | M9: Bloomberg Taxable Muni US Agg Eligible Avg OAS | N9: BTXMOAS Index | O9: 신규
B10: Loans | C10: US Loan | D10: =VLOOKUP(D$3,LAST!$B:$P,4,0) -> 95.33 | E10: =IF(VLOOKUP(E$3,LAST!$B:$P,4,0)=$D10,VLOOKUP(E$2,LAST!$B:$P,4,0),VLOOKUP(E$3,LAST!$B:$P,4,0)) -> 95.34 | F10: =IF(VLOOKUP(F$3,LAST!$B:$P,4,0)=$D10,VLOOKUP(F$2,LAST!$B:$P,4,0),VLOOKUP(F$3,LAST!$B:$P,4,0)) -> 95.33 | G10: =IF($D10/E10-1=0,$D10/F10-1,$D10/E10-1) -> -0.00010488777 | H10: =IF(VLOOKUP(H$3,LAST!$B:$P,4,0)=$D10,VLOOKUP(H$2,LAST!$B:$P,4,0),VLOOKUP(H$3,LAST!$B:$P,4,0)) -> 96.64 | I10: =$D10/H10-1 -> -0.013555464 | M10: SPLSTAUSAll Loans PR | N10: SPBDALB Index | O10: 박성덕 선임
C11: Euro Loan | D11: =VLOOKUP(D$3,LAST!$B:$P,5,0) -> 96.1871 | E11: =IF(VLOOKUP(E$3,LAST!$B:$P,5,0)=$D11,VLOOKUP(E$2,LAST!$B:$P,5,0),VLOOKUP(E$3,LAST!$B:$P,5,0)) -> 96.1899 | F11: =IF(VLOOKUP(F$3,LAST!$B:$P,5,0)=$D11,VLOOKUP(F$2,LAST!$B:$P,5,0),VLOOKUP(F$3,LAST!$B:$P,5,0)) -> 96.1439 | G11: =IF($D11/E11-1=0,$D11/F11-1,$D11/E11-1) -> -2.9109085e-05 | H11: =IF(VLOOKUP(H$3,LAST!$B:$P,5,0)=$D11,VLOOKUP(H$2,LAST!$B:$P,5,0),VLOOKUP(H$3,LAST!$B:$P,5,0)) -> 96.6615 | I11: =$D11/H11-1 -> -0.0049078485 | M11: SPBDELB | N11: SPBDELB Index | O11: 박성덕 선임
B12: Currency | C12: 달러인덱스 | D12: =VLOOKUP(D$3,LAST!$B:$P,6,0) -> 99.529 | E12: =IF(VLOOKUP(E$3,LAST!$B:$P,6,0)=$D12,VLOOKUP(E$2,LAST!$B:$P,6,0),VLOOKUP(E$3,LAST!$B:$P,6,0)) -> 99.219 | F12: =IF(VLOOKUP(F$3,LAST!$B:$P,6,0)=$D12,VLOOKUP(F$2,LAST!$B:$P,6,0),VLOOKUP(F$3,LAST!$B:$P,6,0)) -> 98.942 | G12: =IF($D12/E12-1=0,$D12/F12-1,$D12/E12-1) -> 0.0031244016 | H12: =IF(VLOOKUP(H$3,LAST!$B:$P,6,0)=$D12,VLOOKUP(H$2,LAST!$B:$P,6,0),VLOOKUP(H$3,LAST!$B:$P,6,0)) -> 98.322 | I12: =D12/H12-1 -> 0.012275991 | M12: US Dollar Index | N12: DXY Curncy | O12: 김혜진 매니저
C13: USD/KRW | D13: =VLOOKUP(D$3,LAST!$B:$P,7,0) -> 1518.95 | E13: =IF(VLOOKUP(E$3,LAST!$B:$P,7,0)=$D13,VLOOKUP(E$2,LAST!$B:$P,7,0),VLOOKUP(E$3,LAST!$B:$P,7,0)) -> 1513.05 | F13: =IF(VLOOKUP(F$3,LAST!$B:$P,7,0)=$D13,VLOOKUP(F$2,LAST!$B:$P,7,0),VLOOKUP(F$3,LAST!$B:$P,7,0)) -> 1503.95 | G13: =IF($D13/E13-1=0,$D13/F13-1,$D13/E13-1) -> 0.0038994085 | H13: =IF(VLOOKUP(H$3,LAST!$B:$P,7,0)=$D13,VLOOKUP(H$2,LAST!$B:$P,7,0),VLOOKUP(H$3,LAST!$B:$P,7,0)) -> 1439.75 | I13: =D13/H13-1 -> 0.05500955 | M13: USDKRW 현물환율 | N13: KRW KRWT Curncy | O13: 김혜진 매니저 | P13: 김지호 매니저 | Q13: 45077 | R13: KRW REGN Curncy
C14: EUR/USD | D14: =VLOOKUP(D$3,LAST!$B:$P,8,0) -> 1.1597 | E14: =IF(VLOOKUP(E$3,LAST!$B:$P,8,0)=$D14,VLOOKUP(E$2,LAST!$B:$P,8,0),VLOOKUP(E$2,LAST!$B:$P,8,0)) -> 1.1631 | F14: =IF(VLOOKUP(F$3,LAST!$B:$P,8,0)=$D14,VLOOKUP(F$2,LAST!$B:$P,8,0),VLOOKUP(F$2,LAST!$B:$P,8,0)) -> 1.1659 | G14: =IF($D14/E14-1=0,$D14/F14-1,$D14/E14-1) -> -0.0029232224 | H14: =IF(VLOOKUP(H$3,LAST!$B:$P,8,0)=$D14,VLOOKUP(H$2,LAST!$B:$P,8,0),VLOOKUP(H$2,LAST!$B:$P,8,0)) -> 1.1746 | I14: =D14/H14-1 -> -0.012685169 | M14: EURUSD 현물환율 | N14: EUR BGN Curncy | O14: 김혜진 매니저
C15: USD/CNY | D15: =VLOOKUP(D$3,LAST!$B:$P,9,0) -> 6.7785 | E15: =IF(VLOOKUP(E$3,LAST!$B:$P,9,0)=$D15,VLOOKUP(E$2,LAST!$B:$P,9,0),VLOOKUP(E$3,LAST!$B:$P,9,0)) -> 6.7638 | F15: =IF(VLOOKUP(F$3,LAST!$B:$P,9,0)=$D15,VLOOKUP(F$2,LAST!$B:$P,9,0),VLOOKUP(F$3,LAST!$B:$P,9,0)) -> 6.7663 | G15: =IF($D15/E15-1=0,$D15/F15-1,$D15/E15-1) -> 0.0021733345 | H15: =IF(VLOOKUP(H$3,LAST!$B:$P,9,0)=$D15,VLOOKUP(H$2,LAST!$B:$P,9,0),VLOOKUP(H$3,LAST!$B:$P,9,0)) -> 6.988 | I15: =D15/H15-1 -> -0.029979966 | M15: USDCNY 현물환율 | N15: CNY CURNCY | O15: 김혜진 매니저
C16: BRL/KRW | D16: =VLOOKUP(D$3,LAST!$B:$P,10,0) -> 303.0253 | E16: =IF(VLOOKUP(E$3,LAST!$B:$P,10,0)=$D16,VLOOKUP(E$2,LAST!$B:$P,10,0),VLOOKUP(E$3,LAST!$B:$P,10,0)) -> 303.2977 | F16: =IF(VLOOKUP(F$3,LAST!$B:$P,10,0)=$D16,VLOOKUP(F$2,LAST!$B:$P,10,0),VLOOKUP(F$3,LAST!$B:$P,10,0)) -> 298.7618 | G16: =IF($D16/E16-1=0,$D16/F16-1,$D16/E16-1) -> -0.00089812748 | H16: =IF(VLOOKUP(H$3,LAST!$B:$P,10,0)=$D16,VLOOKUP(H$2,LAST!$B:$P,10,0),VLOOKUP(H$3,LAST!$B:$P,10,0)) -> 262.8661 | I16: =D16/H16-1 -> 0.15277436 | M16: BRLKRW 현물환율 | N16: BRLKRW INDEX | O16: 김혜진 매니저
B17: Commodities | C17: 비트코인 | D17: =VLOOKUP(D$3,LAST!$B:$P,11,0) -> 65585 | E17: =IF(VLOOKUP(E$3,LAST!$B:$P,11,0)=$D17,VLOOKUP(E$2,LAST!$B:$P,11,0),VLOOKUP(E$3,LAST!$B:$P,11,0)) -> 67395 | F17: =IF(VLOOKUP(F$3,LAST!$B:$P,11,0)=$D17,VLOOKUP(F$2,LAST!$B:$P,11,0),VLOOKUP(F$3,LAST!$B:$P,11,0)) -> 72766.96 | G17: =IF($D17/E17-1=0,$D17/F17-1,$D17/E17-1) -> -0.026856592 | H17: =IF(VLOOKUP(H$3,LAST!$B:$P,11,0)=$D17,VLOOKUP(H$2,LAST!$B:$P,11,0),VLOOKUP(H$3,LAST!$B:$P,11,0)) -> 87885 | I17: =D17/H17-1 -> -0.25374068 | M17: Generic 1st BTC Future | N17: BTC1 Curncy | O17: 김혜진 매니저
C18: 해상운임 (BDI) | D18: =VLOOKUP(D$3,LAST!$B:$Z,20,0) -> 3205 | E18: =IF(VLOOKUP(E$3,LAST!$B:$Z,20,0)=$D18,VLOOKUP(E$2,LAST!$B:$Z,20,0),VLOOKUP(E$3,LAST!$B:$Z,20,0)) -> 3222 | F18: =IF(VLOOKUP(F$3,LAST!$B:$Z,20,0)=$D18,VLOOKUP(F$2,LAST!$B:$Z,20,0),VLOOKUP(F$3,LAST!$B:$Z,20,0)) -> 3224 | G18: =IF($D18/E18-1=0,$D18/F18-1,$D18/E18-1) -> -0.0052762259 | H18: =IF(VLOOKUP(H$3,LAST!$B:$Z,20,0)=$D18,VLOOKUP(H$2,LAST!$B:$Z,20,0),VLOOKUP(H$3,LAST!$B:$Z,20,0)) -> 1877 | I18: =D18/H18-1 -> 0.70751199 | M18: BDI Baltic Exchange Dry Index | N18: BDIY Index | O18: 신규
C19: WTI | D19: =VLOOKUP(D$3,LAST!$B:$P,12,0) -> 96.02 | E19: =IF(VLOOKUP(E$3,LAST!$B:$P,12,0)=$D19,VLOOKUP(E$2,LAST!$B:$P,12,0),VLOOKUP(E$3,LAST!$B:$P,12,0)) -> 93.76 | F19: =IF(VLOOKUP(F$3,LAST!$B:$P,12,0)=$D19,VLOOKUP(F$2,LAST!$B:$P,12,0),VLOOKUP(F$3,LAST!$B:$P,12,0)) -> 87.36 | G19: =IF($D19/E19-1=0,$D19/F19-1,$D19/E19-1) -> 0.024104096 | H19: =IF(VLOOKUP(H$3,LAST!$B:$P,12,0)=$D19,VLOOKUP(H$2,LAST!$B:$P,12,0),VLOOKUP(H$3,LAST!$B:$P,12,0)) -> 57.04 | I19: =D19/H19-1 -> 0.68338008 | M19: WTI($) | N19: CLA COMDTY | O19: 김혜진 매니저
C20: 금 | D20: =VLOOKUP(D$3,LAST!$B:$P,13,0) -> 4434.81 | E20: =IF(VLOOKUP(E$3,LAST!$B:$P,13,0)=$D20,VLOOKUP(E$2,LAST!$B:$P,13,0),VLOOKUP(E$3,LAST!$B:$P,13,0)) -> 4488.86 | F20: =IF(VLOOKUP(F$3,LAST!$B:$P,13,0)=$D20,VLOOKUP(F$2,LAST!$B:$P,13,0),VLOOKUP(F$3,LAST!$B:$P,13,0)) -> 4540.26 | G20: =IF($D20/E20-1=0,$D20/F20-1,$D20/E20-1) -> -0.012040919 | H20: =IF(VLOOKUP(H$3,LAST!$B:$P,13,0)=$D20,VLOOKUP(H$2,LAST!$B:$P,13,0),VLOOKUP(H$3,LAST!$B:$P,13,0)) -> 4319.37 | I20: =D20/H20-1 -> 0.02672612 | M20: GOLD($) | N20: XAU CURNCY | O20: 김혜진 매니저
C21: 천연가스 | D21: =VLOOKUP(D$3,LAST!$B:$P,14,0) -> 3.214 | E21: =IF(VLOOKUP(E$3,LAST!$B:$P,14,0)=$D21,VLOOKUP(E$2,LAST!$B:$P,14,0),VLOOKUP(E$3,LAST!$B:$P,14,0)) -> 3.167 | F21: =IF(VLOOKUP(F$3,LAST!$B:$P,14,0)=$D21,VLOOKUP(F$2,LAST!$B:$P,14,0),VLOOKUP(F$3,LAST!$B:$P,14,0)) -> 3.29 | G21: =IF($D21/E21-1=0,$D21/F21-1,$D21/E21-1) -> 0.014840543 | H21: =IF(VLOOKUP(H$3,LAST!$B:$P,14,0)=$D21,VLOOKUP(H$2,LAST!$B:$P,14,0),VLOOKUP(H$3,LAST!$B:$P,14,0)) -> 3.686 | I21: =D21/H21-1 -> -0.12805209 | M21: Generic 1st NG Future | N21: NG1 COMB Comdty | O21: 김혜진 매니저
C22: LNG | D22: =VLOOKUP(D$3,LAST!$B:$P,15,0) -> 18.815 | E22: =IF(VLOOKUP(E$3,LAST!$B:$P,15,0)=$D22,VLOOKUP(E$2,LAST!$B:$P,15,0),VLOOKUP(E$3,LAST!$B:$P,15,0)) -> 18.61 | F22: =IF(VLOOKUP(F$3,LAST!$B:$P,15,0)=$D22,VLOOKUP(F$2,LAST!$B:$P,15,0),VLOOKUP(F$3,LAST!$B:$P,15,0)) -> 18.3 | G22: =IF($D22/E22-1=0,$D22/F22-1,$D22/E22-1) -> 0.011015583 | H22: =IF(VLOOKUP(H$3,LAST!$B:$P,15,0)=$D22,VLOOKUP(H$2,LAST!$B:$P,15,0),VLOOKUP(H$3,LAST!$B:$P,15,0)) -> 9.605 | I22: =D22/H22-1 -> 0.95887559 | M22: LNG Japan/Korea Marker (Platts) Swap | N22: JKL1 COMB Comdty | O22: 김혜진 매니저
B23: Indices | C23: S&P500 | D23: =VLOOKUP(D$3,LAST!$B:$Z,21,0) -> 7553.68 | E23: =IF(VLOOKUP(E$3,LAST!$B:$Z,21,0)=$D23,VLOOKUP(E$2,LAST!$B:$Z,21,0),VLOOKUP(E$3,LAST!$B:$Z,21,0)) -> 7609.78 | F23: =IF(VLOOKUP(F$3,LAST!$B:$Z,21,0)=$D23,VLOOKUP(F$2,LAST!$B:$Z,21,0),VLOOKUP(F$3,LAST!$B:$Z,21,0)) -> 7580.06 | G23: =IF($D23/E23-1=0,$D23/F23-1,$D23/E23-1) -> -0.0073720922 | H23: =IF(VLOOKUP(H$3,LAST!$B:$Z,21,0)=$D23,VLOOKUP(H$2,LAST!$B:$Z,21,0),VLOOKUP(H$3,LAST!$B:$Z,21,0)) -> 6845.5 | I23: =D23/H23-1 -> 0.1034519
C24: NASDAQ | D24: =VLOOKUP(D$3,LAST!$B:$Z,22,0) -> 26853.97 | E24: =IF(VLOOKUP(E$3,LAST!$B:$Z,22,0)=$D24,VLOOKUP(E$2,LAST!$B:$Z,22,0),VLOOKUP(E$3,LAST!$B:$Z,22,0)) -> 27093.9 | F24: =IF(VLOOKUP(F$3,LAST!$B:$Z,22,0)=$D24,VLOOKUP(F$2,LAST!$B:$Z,22,0),VLOOKUP(F$3,LAST!$B:$Z,22,0)) -> 26972.62 | G24: =IF($D24/E24-1=0,$D24/F24-1,$D24/E24-1) -> -0.0088554988 | H24: =IF(VLOOKUP(H$3,LAST!$B:$Z,22,0)=$D24,VLOOKUP(H$2,LAST!$B:$Z,22,0),VLOOKUP(H$3,LAST!$B:$Z,22,0)) -> 23241.99 | I24: =D24/H24-1 -> 0.15540752
C25: 홍콩H (HSCEI) | D25: =VLOOKUP(D$3,LAST!$B:$Z,23,0) -> 8596.59 | E25: =IF(VLOOKUP(E$3,LAST!$B:$Z,23,0)=$D25,VLOOKUP(E$2,LAST!$B:$Z,23,0),VLOOKUP(E$3,LAST!$B:$Z,23,0)) -> 8762.97 | F25: =IF(VLOOKUP(F$3,LAST!$B:$Z,23,0)=$D25,VLOOKUP(F$2,LAST!$B:$Z,23,0),VLOOKUP(F$3,LAST!$B:$Z,23,0)) -> 8425.82 | G25: =IF($D25/E25-1=0,$D25/F25-1,$D25/E25-1) -> -0.018986713 | H25: =IF(VLOOKUP(H$3,LAST!$B:$Z,23,0)=$D25,VLOOKUP(H$2,LAST!$B:$Z,23,0),VLOOKUP(H$3,LAST!$B:$Z,23,0)) -> 8913.68 | I25: =D25/H25-1 -> -0.035573411
C26: 코스피 | D26: =VLOOKUP(D$3,LAST!$B:$Z,24,0) -> 8801.49 | E26: =IF(VLOOKUP(E$3,LAST!$B:$Z,24,0)=$D26,VLOOKUP(E$2,LAST!$B:$Z,24,0),VLOOKUP(E$3,LAST!$B:$Z,24,0)) -> 8788.38 | F26: =IF(VLOOKUP(F$3,LAST!$B:$Z,24,0)=$D26,VLOOKUP(F$2,LAST!$B:$Z,24,0),VLOOKUP(F$3,LAST!$B:$Z,24,0)) -> 8476.15 | G26: =IF($D26/E26-1=0,$D26/F26-1,$D26/E26-1) -> 0.0014917425 | H26: =IF(VLOOKUP(H$3,LAST!$B:$Z,24,0)=$D26,VLOOKUP(H$2,LAST!$B:$Z,24,0),VLOOKUP(H$3,LAST!$B:$Z,24,0)) -> 4214.17 | I26: =D26/H26-1 -> 1.0885465 | M26: 팀장님 지시사항
C27: Nikkei225 | D27: =VLOOKUP(D$3,LAST!$B:$Z,25,0) -> 68402.13 | E27: =IF(VLOOKUP(E$3,LAST!$B:$Z,25,0)=$D27,VLOOKUP(E$2,LAST!$B:$Z,25,0),VLOOKUP(E$3,LAST!$B:$Z,25,0)) -> 66734.24 | F27: =IF(VLOOKUP(F$3,LAST!$B:$Z,25,0)=$D27,VLOOKUP(F$2,LAST!$B:$Z,25,0),VLOOKUP(F$3,LAST!$B:$Z,25,0)) -> 66329.5 | G27: =IF($D27/E27-1=0,$D27/F27-1,$D27/E27-1) -> 0.024993017 | H27: =IF(VLOOKUP(H$3,LAST!$B:$Z,25,0)=$D27,VLOOKUP(H$2,LAST!$B:$Z,25,0),VLOOKUP(H$3,LAST!$B:$Z,25,0)) -> 50339.48 | I27: =D27/H27-1 -> 0.35881678 | M27: 왓츠앱으로 공유 시 표는 그림으로, 주요이슈는 텍스트로 작성하여 공유
B29: [주요 이슈]
B30: - 미-이란 군사적 충돌과 사모신용 우려로 하락 (다우 -1.21%, 나스닥 -0.89%, S&P500 -0.74%)
B31: - 연준이 감독·규제 보고서를 통해 사모신용 관련 위험을 예의주시하고 있다고 언급하자 소프트웨어 업종이 큰 폭으로 하락하며 지수에 부담
B33: [종목별 이슈]
B34: - 마이크론(+1.45%)은 모건스탠리가 메모리 공급 부족과 DRAM 가격 상승을 이유로 목표 주가를 520달러에서 1,050달러로 상향 조정하자 상승
B35: - ASML(+1.23%)은 모건스탠리가 실적 발표 후 논란이 이어지고 있는 생산 능력에 대해 회사측이 내년 90대의 EUV 장비 수요를 충족할 수 있다는 발표를 기반으로 목표주가를 상향 조정하자 상승
B36: - 메타 플랫폼(+4.24%)은 왓츠앱과 인스타그램 전반에 걸쳐 운영 자동화 및 향후 유료 구독 서비스 도입을 지원하는 기업용 AI 비즈니스 에이전트 플랫폼을 출시하자 상승
B37: - 오라클(-5.83%)은 UBS의 목표주가 상향 소식등에도 불구하고 사모신용 이슈가 부각되자 하락. 최근 회사채 발행을 통해 자금 조달을 하고 있는 오라클에게 사모 신용 이슈는 자금 조달 불안을 부각시켜 매물 출회 요인으로 작용
B38: - 팔란티어(-6.55%)도 사이버 보안 회사들의 부진한 실적과 주주총회에서 인권 관련 제안을 부결시키고 기존 지배구조 및 사업 정책을 변경하지 않기로 결정했다는 소식도 부담. 더불어 사모 신용 이슈로 인한 소프트웨어 업종에 대한 부정적인 심리도 영향
B68: 7

Sheet Stat
B3: ■ 5/10년 평균 및 표준편차
B4: 구 분 | C4: EM Spread(bp) | D4: Global HY Spread(bp) | E4: US HY Spread(bp) | F4: US Loan($) | G4: Euro Loan(€) | H4: 달러 인덱스(pt) | I4: 달러원 환율(원) | L4: 행 번호 | M4: 일자 | N4: EM Spread | O4: Global HY Spread | P4: US HY Spread | Q4: US Loan | R4: Euro Loan | S4: 달러 인덱스(pt) | T4: 달러원 환율(원) | W4: EM Spread | X4: Global HY Spread | Y4: US HY Spread | Z4: US Loan | AA4: Euro Loan | AB4: 달러 인덱스(pt) | AC4: 달러원 환율(원)
B5: =Board!$D$3 -> 46176 | C5: =VLOOKUP($M5,LAST!$B:$Q,2,0) -> 215.27 | D5: =VLOOKUP($M5,LAST!$B:$Q,3,0)*100 -> 275.4 | E5: =VLOOKUP($M5,LAST!$B:$Q,16,0)*100 -> 263 | F5: =VLOOKUP($M5,LAST!$B:$Q,4,0) -> 95.33 | G5: =VLOOKUP($M5,LAST!$B:$Q,5,0) -> 96.1871 | H5: =VLOOKUP($M5,LAST!$B:$Q,6,0) -> 99.529 | I5: =VLOOKUP($M5,LAST!$B:$Q,7,0) -> 1518.95 | L5: =ROW(M5) -> 5 | M5: =B5 -> 46176 | N5: =W5/W6-1 -> 0.0016285129 | O5: =X5/X6-1 -> 0.0075732631 | P5: =Y5/Y6-1 -> 0.023346304 | Q5: =Z5/Z6-1 -> 0 | R5: =AA5/AA6-1 -> -2.9109085e-05 | S5: =AB5/AB6-1 -> 0.0031244016 | T5: =AC5/AC6-1 -> 0 | V5: =M5 -> 46176 | W5: =VLOOKUP($M5,LAST!$B:$Q,2,0) -> 215.27 | X5: =VLOOKUP($M5,LAST!$B:$Q,3,0)*100 -> 275.4 | Y5: =VLOOKUP($M5,LAST!$B:$Q,16,0)*100 -> 263 | Z5: =VLOOKUP($M5,LAST!$B:$Q,4,0) -> 95.33 | AA5: =VLOOKUP($M5,LAST!$B:$Q,5,0) -> 96.1871 | AB5: =VLOOKUP($M5,LAST!$B:$Q,6,0) -> 99.529 | AC5: =VLOOKUP($M5,LAST!$B:$Q,7,0) -> 1518.95
A6: 행 번호 | B6: 직전 5년 평균 | C6: =AVERAGEIFS($W:$W,$M:$M,">="&DATE(YEAR($B$5)-5,MONTH($B$5),DAY($B$5))) -> 331.13891 | D6: =AVERAGEIFS($X:$X,$M:$M,">="&DATE(YEAR($B$5)-5,MONTH($B$5),DAY($B$5))) -> 415.8429 | E6: =AVERAGEIFS($Y:$Y,$M:$M,">="&DATE(YEAR($B$5)-5,MONTH($B$5),DAY($B$5))) -> 344.58544 | F6: =AVERAGEIFS($Z:$Z,$M:$M,">="&DATE(YEAR($B$5)-5,MONTH($B$5),DAY($B$5))) -> 96.018782 | G6: =AVERAGEIFS($AA:$AA,$M:$M,">="&DATE(YEAR($B$5)-5,MONTH($B$5),DAY($B$5))) -> 96.162484 | H6: =AVERAGEIFS($AB:$AB,$M:$M,">="&DATE(YEAR($B$5)-5,MONTH($B$5),DAY($B$5))) -> 101.62366 | I6: =AVERAGEIFS($AC:$AC,$M:$M,">="&DATE(YEAR($B$5)-5,MONTH($B$5),DAY($B$5))) -> 1335.8896 | L6: =ROW(M6) -> 6 | M6: =WORKDAY(M5,-1) -> 46175 | N6: =W6/W7-1 -> -0.017508571 | O6: =X6/X7-1 -> -0.0074803007 | P6: =Y6/Y7-1 -> -0.0077220077 | Q6: =Z6/Z7-1 -> -0.00010488777 | R6: =AA6/AA7-1 -> 0.00015388599 | S6: =AB6/AB7-1 -> 0.00018144978 | T6: =AC6/AC7-1 -> 0.0038994085 | V6: =M6 -> 46175 | W6: =VLOOKUP($M6,LAST!$B:$Q,2,0) -> 214.92 | X6: =VLOOKUP($M6,LAST!$B:$Q,3,0)*100 -> 273.33 | Y6: =VLOOKUP($M6,LAST!$B:$Q,16,0)*100 -> 257 | Z6: =VLOOKUP($M6,LAST!$B:$Q,4,0) -> 95.33 | AA6: =VLOOKUP($M6,LAST!$B:$Q,5,0) -> 96.1899 | AB6: =VLOOKUP($M6,LAST!$B:$Q,6,0) -> 99.219 | AC6: =VLOOKUP($M6,LAST!$B:$Q,7,0) -> 1518.95
A7: =INDEX($L:$L,MATCH(VLOOKUP(WORKDAY(DATE(YEAR($B$5)-5,MONTH($B$5),DAY($B$5)),0),$M:$M,1,0),M:M,0)) -> 1309 | B7: 직전5년 표준편차 | C7: =STDEV(N5:N1310)*SQRT(250) -> 0.24133549 | D7: =STDEV(O5:O1310)*SQRT(250) -> 0.26034648 | E7: =STDEV(P5:P1310)*SQRT(250) -> 0.35918668 | F7: =STDEV(Q5:Q1310)*SQRT(250) -> 0.017382928 | G7: =STDEV(R5:R1310)*SQRT(250) -> 0.019591942 | H7: =STDEV(S5:S1310)*SQRT(250) -> 0.069161844 | I7: =STDEV(T5:T1310)*SQRT(250) -> 0.090026425 | L7: =ROW(M7) -> 7 | M7: =WORKDAY(M6,-1) -> 46174 | N7: =W7/W8-1 -> 0.019528337 | O7: =X7/X8-1 -> -0.0073174248 | P7: =Y7/Y8-1 -> 0.0077821012 | Q7: =Z7/Z8-1 -> 0.00020981956 | R7: =AA7/AA8-1 -> 0.00032451357 | S7: =AB7/AB8-1 -> 0.0026176952 | T7: =AC7/AC8-1 -> 0.0060507331 | V7: =M7 -> 46174 | W7: =VLOOKUP($M7,LAST!$B:$Q,2,0) -> 218.75 | X7: =VLOOKUP($M7,LAST!$B:$Q,3,0)*100 -> 275.39 | Y7: =VLOOKUP($M7,LAST!$B:$Q,16,0)*100 -> 259 | Z7: =VLOOKUP($M7,LAST!$B:$Q,4,0) -> 95.34 | AA7: =VLOOKUP($M7,LAST!$B:$Q,5,0) -> 96.1751 | AB7: =VLOOKUP($M7,LAST!$B:$Q,6,0) -> 99.201 | AC7: =VLOOKUP($M7,LAST!$B:$Q,7,0) -> 1513.05
C8: =C6*C7 -> 79.915573 | D8: =D6*D7 -> 108.26323 | E8: =E6*E7 -> 123.7705 | F8: =F6*F7 -> 1.6690876 | G8: =G6*G7 -> 1.8840098 | H8: =H6*H7 -> 7.02848 | I8: =I6*I7 -> 120.26537 | L8: =ROW(M8) -> 8 | M8: =WORKDAY(M7,-1) -> 46171 | N8: =W8/W9-1 -> -0.015734667 | O8: =X8/X9-1 -> -0.012810476 | P8: =Y8/Y9-1 -> -0.01532567 | Q8: =Z8/Z9-1 -> 0.00073490814 | R8: =AA8/AA9-1 -> -0.00024020714 | S8: =AB8/AB9-1 -> -0.00078771965 | T8: =AC8/AC9-1 -> 0.0065252309 | V8: =M8 -> 46171 | W8: =VLOOKUP($M8,LAST!$B:$Q,2,0) -> 214.56 | X8: =VLOOKUP($M8,LAST!$B:$Q,3,0)*100 -> 277.42 | Y8: =VLOOKUP($M8,LAST!$B:$Q,16,0)*100 -> 257 | Z8: =VLOOKUP($M8,LAST!$B:$Q,4,0) -> 95.32 | AA8: =VLOOKUP($M8,LAST!$B:$Q,5,0) -> 96.1439 | AB8: =VLOOKUP($M8,LAST!$B:$Q,6,0) -> 98.942 | AC8: =VLOOKUP($M8,LAST!$B:$Q,7,0) -> 1503.95
B9: 5년 평균+2𝜎 | C9: =C11*(1+2*C7) -> 490.97006 | D9: =D11*(1+2*D7) -> 632.36936 | E9: =E11*(1+2*E7) -> 592.12644 | F9: =F11*(1+2*F7) -> 99.356957 | G9: =G11*(1+2*G7) -> 99.930504 | H9: =H11*(1+2*H7) -> 115.68062 | I9: =I11*(1+2*I7) -> 1576.4204 | L9: =ROW(M9) -> 9 | M9: =WORKDAY(M8,-1) -> 46170 | N9: =W9/W10-1 -> -0.0022427682 | O9: =X9/X10-1 -> -0.0015278025 | P9: =Y9/Y10-1 -> 0 | Q9: =Z9/Z10-1 -> -0.00010497586 | R9: =AA9/AA10-1 -> -0.00011541089 | S9: =AB9/AB10-1 -> -0.0018748866 | T9: =AC9/AC10-1 -> -0.0035012838 | V9: =M9 -> 46170 | W9: =VLOOKUP($M9,LAST!$B:$Q,2,0) -> 217.99 | X9: =VLOOKUP($M9,LAST!$B:$Q,3,0)*100 -> 281.02 | Y9: =VLOOKUP($M9,LAST!$B:$Q,16,0)*100 -> 261 | Z9: =VLOOKUP($M9,LAST!$B:$Q,4,0) -> 95.25 | AA9: =VLOOKUP($M9,LAST!$B:$Q,5,0) -> 96.167 | AB9: =VLOOKUP($M9,LAST!$B:$Q,6,0) -> 99.02 | AC9: =VLOOKUP($M9,LAST!$B:$Q,7,0) -> 1494.2
B10: 5년 평균+1𝜎 | C10: =C11*(1+1*C7) -> 411.05448 | D10: =D11*(1+1*D7) -> 524.10613 | E10: =E11*(1+1*E7) -> 468.35594 | F10: =F11*(1+1*F7) -> 97.687869 | G10: =G11*(1+1*G7) -> 98.046494 | H10: =H11*(1+1*H7) -> 108.65214 | I10: =I11*(1+1*I7) -> 1456.155 | L10: =ROW(M10) -> 10 | M10: =WORKDAY(M9,-1) -> 46169 | N10: =W10/W11-1 -> -0.015101654 | O10: =X10/X11-1 -> -0.006950815 | P10: =Y10/Y11-1 -> 0 | Q10: =Z10/Z11-1 -> -0.00010496484 | R10: =AA10/AA11-1 -> -0.00012683192 | S10: =AB10/AB11-1 -> 0.00037310046 | T10: =AC10/AC11-1 -> -0.0053729561 | V10: =M10 -> 46169 | W10: =VLOOKUP($M10,LAST!$B:$Q,2,0) -> 218.48 | X10: =VLOOKUP($M10,LAST!$B:$Q,3,0)*100 -> 281.45 | Y10: =VLOOKUP($M10,LAST!$B:$Q,16,0)*100 -> 261 | Z10: =VLOOKUP($M10,LAST!$B:$Q,4,0) -> 95.26 | AA10: =VLOOKUP($M10,LAST!$B:$Q,5,0) -> 96.1781 | AB10: =VLOOKUP($M10,LAST!$B:$Q,6,0) -> 99.206 | AC10: =VLOOKUP($M10,LAST!$B:$Q,7,0) -> 1499.45
B11: 직전5년 평균 | C11: =C6 -> 331.13891 | D11: =D6 -> 415.8429 | E11: =E6 -> 344.58544 | F11: =F6 -> 96.018782 | G11: =G6 -> 96.162484 | H11: =H6 -> 101.62366 | I11: =I6 -> 1335.8896 | L11: =ROW(M11) -> 11 | M11: =WORKDAY(M10,-1) -> 46168 | N11: =W11/W12-1 -> 0.004619356 | O11: =X11/X12-1 -> 0.00056485208 | P11: =Y11/Y12-1 -> 0.0038461538 | Q11: =Z11/Z12-1 -> 0.00020997375 | R11: =AA11/AA12-1 -> -4.2622024e-05 | S11: =AB11/AB12-1 -> -0.00070536785 | T11: =AC11/AC12-1 -> -0.0065895687 | V11: =M11 -> 46168 | W11: =VLOOKUP($M11,LAST!$B:$Q,2,0) -> 221.83 | X11: =VLOOKUP($M11,LAST!$B:$Q,3,0)*100 -> 283.42 | Y11: =VLOOKUP($M11,LAST!$B:$Q,16,0)*100 -> 261 | Z11: =VLOOKUP($M11,LAST!$B:$Q,4,0) -> 95.27 | AA11: =VLOOKUP($M11,LAST!$B:$Q,5,0) -> 96.1903 | AB11: =VLOOKUP($M11,LAST!$B:$Q,6,0) -> 99.169 | AC11: =VLOOKUP($M11,LAST!$B:$Q,7,0) -> 1507.55
B12: 5년 평균-1𝜎 | C12: =C11*(1-1*C7) -> 251.22334 | D12: =D11*(1-1*D7) -> 307.57966 | E12: =E11*(1-1*E7) -> 220.81494 | F12: =F11*(1-1*F7) -> 94.349694 | G12: =G11*(1-1*G7) -> 94.278474 | H12: =H11*(1-1*H7) -> 94.595184 | I12: =I11*(1-1*I7) -> 1215.6243 | L12: =ROW(M12) -> 12 | M12: =WORKDAY(M11,-1) -> 46167 | N12: =W12/W13-1 -> 0 | O12: =X12/X13-1 -> 0.0025837964 | P12: =Y12/Y13-1 -> 0 | Q12: =Z12/Z13-1 -> 0.0001049979 | R12: =AA12/AA13-1 -> 7.5893753e-05 | S12: =AB12/AB13-1 -> 0 | T12: =AC12/AC13-1 -> 0 | V12: =M12 -> 46167 | W12: =VLOOKUP($M12,LAST!$B:$Q,2,0) -> 220.81 | X12: =VLOOKUP($M12,LAST!$B:$Q,3,0)*100 -> 283.26 | Y12: =VLOOKUP($M12,LAST!$B:$Q,16,0)*100 -> 260 | Z12: =VLOOKUP($M12,LAST!$B:$Q,4,0) -> 95.25 | AA12: =VLOOKUP($M12,LAST!$B:$Q,5,0) -> 96.1944 | AB12: =VLOOKUP($M12,LAST!$B:$Q,6,0) -> 99.239 | AC12: =VLOOKUP($M12,LAST!$B:$Q,7,0) -> 1517.55
B13: 5년 평균-2𝜎 | C13: =C11*(1-2*C7) -> 171.30777 | D13: =D11*(1-2*D7) -> 199.31643 | E13: =E11*(1-2*E7) -> 97.044443 | F13: =F11*(1-2*F7) -> 92.680607 | G13: =G11*(1-2*G7) -> 92.394464 | H13: =H11*(1-2*H7) -> 87.566704 | I13: =I11*(1-2*I7) -> 1095.3589 | L13: =ROW(M13) -> 13 | M13: =WORKDAY(M12,-1) -> 46164 | N13: =W13/W14-1 -> -0.017486874 | O13: =X13/X14-1 -> -0.016876609 | P13: =Y13/Y14-1 -> -0.026217228 | Q13: =Z13/Z14-1 -> -0.00010498688 | R13: =AA13/AA14-1 -> 3.2229893e-05 | S13: =AB13/AB14-1 -> -0.00018134741 | T13: =AC13/AC14-1 -> 0.0059993371 | V13: =M13 -> 46164 | W13: =VLOOKUP($M13,LAST!$B:$Q,2,0) -> 220.81 | X13: =VLOOKUP($M13,LAST!$B:$Q,3,0)*100 -> 282.53 | Y13: =VLOOKUP($M13,LAST!$B:$Q,16,0)*100 -> 260 | Z13: =VLOOKUP($M13,LAST!$B:$Q,4,0) -> 95.24 | AA13: =VLOOKUP($M13,LAST!$B:$Q,5,0) -> 96.1871 | AB13: =VLOOKUP($M13,LAST!$B:$Q,6,0) -> 99.239 | AC13: =VLOOKUP($M13,LAST!$B:$Q,7,0) -> 1517.55
A14: 행 번호 | B14: 직전 10년 평균 | C14: =AVERAGEIFS($W:$W,$M:$M,">="&DATE(YEAR($B$5)-10,MONTH($B$5),DAY($B$5))) -> 345.50939 | D14: =AVERAGEIFS($X:$X,$M:$M,">="&DATE(YEAR($B$5)-10,MONTH($B$5),DAY($B$5))) -> 433.89673 | E14: =AVERAGEIFS($Y:$Y,$M:$M,">="&DATE(YEAR($B$5)-10,MONTH($B$5),DAY($B$5))) -> 378.67344 | F14: =AVERAGEIFS($Z:$Z,$M:$M,">="&DATE(YEAR($B$5)-10,MONTH($B$5),DAY($B$5))) -> 96.103396 | G14: =AVERAGEIFS($AA:$AA,$M:$M,">="&DATE(YEAR($B$5)-10,MONTH($B$5),DAY($B$5))) -> 96.940507 | H14: =AVERAGEIFS($AB:$AB,$M:$M,">="&DATE(YEAR($B$5)-10,MONTH($B$5),DAY($B$5))) -> 98.622576 | I14: =AVERAGEIFS($AC:$AC,$M:$M,">="&DATE(YEAR($B$5)-10,MONTH($B$5),DAY($B$5))) -> 1238.8478 | L14: =ROW(M14) -> 14 | M14: =WORKDAY(M13,-1) -> 46163 | N14: =W14/W15-1 -> 0.0043348081 | O14: =X14/X15-1 -> -0.0008691722 | P14: =Y14/Y15-1 -> -0.0037313433 | Q14: =Z14/Z15-1 -> -0.00020992967 | R14: =AA14/AA15-1 -> -6.341609e-05 | S14: =AB14/AB15-1 -> 0.0016651193 | T14: =AC14/AC15-1 -> 0.0076820307 | V14: =M14 -> 46163 | W14: =VLOOKUP($M14,LAST!$B:$Q,2,0) -> 224.74 | X14: =VLOOKUP($M14,LAST!$B:$Q,3,0)*100 -> 287.38 | Y14: =VLOOKUP($M14,LAST!$B:$Q,16,0)*100 -> 267 | Z14: =VLOOKUP($M14,LAST!$B:$Q,4,0) -> 95.25 | AA14: =VLOOKUP($M14,LAST!$B:$Q,5,0) -> 96.184 | AB14: =VLOOKUP($M14,LAST!$B:$Q,6,0) -> 99.257 | AC14: =VLOOKUP($M14,LAST!$B:$Q,7,0) -> 1508.5
A15: =IFERROR(INDEX($L:$L,MATCH(VLOOKUP(WORKDAY(DATE(YEAR($B$5)-10,MONTH($B$5),DAY($B$5)),0),$M:$M,1,0),M:M,0)),INDEX($L:$L,MATCH(VLOOKUP(WORKDAY(DATE(YEAR($B$5)-10,MONTH($B$5),DAY($B$5)),0)-1,$M:$M,1,0),M:M,0))) -> 2613 | B15: 직전10년 표준편차 | C15: =STDEV(N5:N2615)*SQRT(250) -> 0.25065209 | D15: =STDEV(O5:O2615)*SQRT(250) -> 0.26150182 | E15: =STDEV(P5:P2615)*SQRT(250) -> 0.34641951 | F15: =STDEV(Q5:Q2615)*SQRT(250) -> 0.033912958 | G15: =STDEV(R5:R2615)*SQRT(250) -> 0.029010577 | H15: =STDEV(S5:S2615)*SQRT(250) -> 0.064762361 | I15: =STDEV(T5:T2615)*SQRT(250) -> 0.083825752 | L15: =ROW(M15) -> 15 | M15: =WORKDAY(M14,-1) -> 46162 | N15: =W15/W16-1 -> 0.009929142 | O15: =X15/X16-1 -> -0.0015620661 | P15: =Y15/Y16-1 -> -0.018315018 | Q15: =Z15/Z16-1 -> -0.00041968314 | R15: =AA15/AA16-1 -> -0.00011954063 | S15: =AB15/AB16-1 -> -0.0023659227 | T15: =AC15/AC16-1 -> -0.0093965061 | V15: =M15 -> 46162 | W15: =VLOOKUP($M15,LAST!$B:$Q,2,0) -> 223.77 | X15: =VLOOKUP($M15,LAST!$B:$Q,3,0)*100 -> 287.63 | Y15: =VLOOKUP($M15,LAST!$B:$Q,16,0)*100 -> 268 | Z15: =VLOOKUP($M15,LAST!$B:$Q,4,0) -> 95.27 | AA15: =VLOOKUP($M15,LAST!$B:$Q,5,0) -> 96.1901 | AB15: =VLOOKUP($M15,LAST!$B:$Q,6,0) -> 99.092 | AC15: =VLOOKUP($M15,LAST!$B:$Q,7,0) -> 1497
C16: =C14*C15 -> 86.60265 | D16: =D14*D15 -> 113.46478 | E16: =E14*E15 -> 131.17987 | F16: =F14*F15 -> 3.2591504 | G16: =G14*G15 -> 2.8123001 | H16: =H14*H15 -> 6.3870309 | I16: =I14*I15 -> 103.84735 | L16: =ROW(M16) -> 16 | M16: =WORKDAY(M15,-1) -> 46161 | N16: =W16/W17-1 -> 0.0038965158 | O16: =X16/X17-1 -> 0.0024009186 | P16: =Y16/Y17-1 -> 0.0036764706 | Q16: =Z16/Z17-1 -> -0.00041950708 | R16: =AA16/AA17-1 -> 0.00015490707 | S16: =AB16/AB17-1 -> 0.0013509018 | T16: =AC16/AC17-1 -> 0.011614285 | V16: =M16 -> 46161 | W16: =VLOOKUP($M16,LAST!$B:$Q,2,0) -> 221.57 | X16: =VLOOKUP($M16,LAST!$B:$Q,3,0)*100 -> 288.08 | Y16: =VLOOKUP($M16,LAST!$B:$Q,16,0)*100 -> 273 | Z16: =VLOOKUP($M16,LAST!$B:$Q,4,0) -> 95.31 | AA16: =VLOOKUP($M16,LAST!$B:$Q,5,0) -> 96.2016 | AB16: =VLOOKUP($M16,LAST!$B:$Q,6,0) -> 99.327 | AC16: =VLOOKUP($M16,LAST!$B:$Q,7,0) -> 1511.2
B17: 10년 평균+2𝜎 | C17: =C19*(1+2*C15) -> 518.71469 | D17: =D19*(1+2*D15) -> 660.8263 | E17: =E19*(1+2*E15) -> 641.03317 | F17: =F19*(1+2*F15) -> 102.6217 | G17: =G19*(1+2*G15) -> 102.56511 | H17: =H19*(1+2*H15) -> 111.39664 | I17: =I19*(1+2*I15) -> 1446.5426 | L17: =ROW(M17) -> 17 | M17: =WORKDAY(M16,-1) -> 46160 | N17: =W17/W18-1 -> 0.021758252 | O17: =X17/X18-1 -> 0.017453799 | P17: =Y17/Y18-1 -> 0.018726592 | Q17: =Z17/Z18-1 -> 0.00010488777 | R17: =AA17/AA18-1 -> 0.0019427043 | S17: =AB17/AB18-1 -> -0.00091656259 | T17: =AC17/AC18-1 -> -0.0028036447 | V17: =M17 -> 46160 | W17: =VLOOKUP($M17,LAST!$B:$Q,2,0) -> 220.71 | X17: =VLOOKUP($M17,LAST!$B:$Q,3,0)*100 -> 287.39 | Y17: =VLOOKUP($M17,LAST!$B:$Q,16,0)*100 -> 272 | Z17: =VLOOKUP($M17,LAST!$B:$Q,4,0) -> 95.35 | AA17: =VLOOKUP($M17,LAST!$B:$Q,5,0) -> 96.1867 | AB17: =VLOOKUP($M17,LAST!$B:$Q,6,0) -> 99.193 | AC17: =VLOOKUP($M17,LAST!$B:$Q,7,0) -> 1493.85
B18: 10년 평균+1𝜎 | C18: =C19*(1+1*C15) -> 432.11204 | D18: =D19*(1+1*D15) -> 547.36151 | E18: =E19*(1+1*E15) -> 509.85331 | F18: =F19*(1+1*F15) -> 99.362546 | G18: =G19*(1+1*G15) -> 99.752807 | H18: =H19*(1+1*H15) -> 105.00961 | I18: =I19*(1+1*I15) -> 1342.6952 | L18: =ROW(M18) -> 18 | M18: =WORKDAY(M17,-1) -> 46157 | N18: =W18/W19-1 -> 0.0077443434 | O18: =X18/X19-1 -> 0.0061266652 | P18: =Y18/Y19-1 -> 0.011363636 | Q18: =Z18/Z19-1 -> -0.00083839866 | R18: =AA18/AA19-1 -> 0.00025735735 | S18: =AB18/AB19-1 -> 0.0047055728 | T18: =AC18/AC19-1 -> 0.0036177269 | V18: =M18 -> 46157 | W18: =VLOOKUP($M18,LAST!$B:$Q,2,0) -> 216.01 | X18: =VLOOKUP($M18,LAST!$B:$Q,3,0)*100 -> 282.46 | Y18: =VLOOKUP($M18,LAST!$B:$Q,16,0)*100 -> 267 | Z18: =VLOOKUP($M18,LAST!$B:$Q,4,0) -> 95.34 | AA18: =VLOOKUP($M18,LAST!$B:$Q,5,0) -> 96.0002 | AB18: =VLOOKUP($M18,LAST!$B:$Q,6,0) -> 99.284 | AC18: =VLOOKUP($M18,LAST!$B:$Q,7,0) -> 1498.05
B19: 직전10년 평균 | C19: =C14 -> 345.50939 | D19: =D14 -> 433.89673 | E19: =E14 -> 378.67344 | F19: =F14 -> 96.103396 | G19: =G14 -> 96.940507 | H19: =H14 -> 98.622576 | I19: =I14 -> 1238.8478 | L19: =ROW(M19) -> 19 | M19: =WORKDAY(M18,-1) -> 46156 | N19: =W19/W20-1 -> -0.0059821925 | O19: =X19/X20-1 -> -0.006581741 | P19: =Y19/Y20-1 -> -0.011235955 | Q19: =Z19/Z20-1 -> 0.00020964361 | R19: =AA19/AA20-1 -> 0.00051185075 | S19: =AB19/AB20-1 -> 0.0029941943 | T19: =AC19/AC20-1 -> 0.0023503341 | V19: =M19 -> 46156 | W19: =VLOOKUP($M19,LAST!$B:$Q,2,0) -> 214.35 | X19: =VLOOKUP($M19,LAST!$B:$Q,3,0)*100 -> 280.74 | Y19: =VLOOKUP($M19,LAST!$B:$Q,16,0)*100 -> 264 | Z19: =VLOOKUP($M19,LAST!$B:$Q,4,0) -> 95.42 | AA19: =VLOOKUP($M19,LAST!$B:$Q,5,0) -> 95.9755 | AB19: =VLOOKUP($M19,LAST!$B:$Q,6,0) -> 98.819 | AC19: =VLOOKUP($M19,LAST!$B:$Q,7,0) -> 1492.65
B20: 10년 평균-1𝜎 | C20: =C19*(1-1*C15) -> 258.90674 | D20: =D19*(1-1*D15) -> 320.43195 | E20: =E19*(1-1*E15) -> 247.49357 | F20: =F19*(1-1*F15) -> 92.844246 | G20: =G19*(1-1*G15) -> 94.128206 | H20: =H19*(1-1*H15) -> 92.235546 | I20: =I19*(1-1*I15) -> 1135.0005 | L20: =ROW(M20) -> 20 | M20: =WORKDAY(M19,-1) -> 46155 | N20: =W20/W21-1 -> 0.0049867176 | O20: =X20/X21-1 -> -0.0011663662 | P20: =Y20/Y21-1 -> -0.0037313433 | Q20: =Z20/Z21-1 -> 0.00010483279 | R20: =AA20/AA21-1 -> 0.00067388678 | S20: =AB20/AB21-1 -> 0.0022991312 | T20: =AC20/AC21-1 -> -0.0026789003 | V20: =M20 -> 46155 | W20: =VLOOKUP($M20,LAST!$B:$Q,2,0) -> 215.64 | X20: =VLOOKUP($M20,LAST!$B:$Q,3,0)*100 -> 282.6 | Y20: =VLOOKUP($M20,LAST!$B:$Q,16,0)*100 -> 267 | Z20: =VLOOKUP($M20,LAST!$B:$Q,4,0) -> 95.4 | AA20: =VLOOKUP($M20,LAST!$B:$Q,5,0) -> 95.9264 | AB20: =VLOOKUP($M20,LAST!$B:$Q,6,0) -> 98.524 | AC20: =VLOOKUP($M20,LAST!$B:$Q,7,0) -> 1489.15
B21: 10년 평균-2𝜎 | C21: =C19*(1-2*C15) -> 172.30409 | D21: =D19*(1-2*D15) -> 206.96716 | E21: =E19*(1-2*E15) -> 116.3137 | F21: =F19*(1-2*F15) -> 89.585095 | G21: =G19*(1-2*G15) -> 91.315906 | H21: =H19*(1-2*H15) -> 85.848515 | I21: =I19*(1-2*I15) -> 1031.1531 | L21: =ROW(M21) -> 21 | M21: =WORKDAY(M20,-1) -> 46154 | N21: =W21/W22-1 -> 0.00487051 | O21: =X21/X22-1 -> 0.0075137098 | P21: =Y21/Y22-1 -> 0.015151515 | Q21: =Z21/Z22-1 -> -0.00020962163 | R21: =AA21/AA22-1 -> 0.00025042311 | S21: =AB21/AB22-1 -> 0.0035016079 | T21: =AC21/AC22-1 -> 0.014023769 | V21: =M21 -> 46154 | W21: =VLOOKUP($M21,LAST!$B:$Q,2,0) -> 214.57 | X21: =VLOOKUP($M21,LAST!$B:$Q,3,0)*100 -> 282.93 | Y21: =VLOOKUP($M21,LAST!$B:$Q,16,0)*100 -> 268 | Z21: =VLOOKUP($M21,LAST!$B:$Q,4,0) -> 95.39 | AA21: =VLOOKUP($M21,LAST!$B:$Q,5,0) -> 95.8618 | AB21: =VLOOKUP($M21,LAST!$B:$Q,6,0) -> 98.298 | AC21: =VLOOKUP($M21,LAST!$B:$Q,7,0) -> 1493.15
L22: =ROW(M22) -> 22 | M22: =WORKDAY(M21,-1) -> 46153 | N22: =W22/W23-1 -> -0.012303992 | O22: =X22/X23-1 -> -0.011649597 | P22: =Y22/Y23-1 -> -0.007518797 | Q22: =Z22/Z23-1 -> 0.0001048218 | R22: =AA22/AA23-1 -> 0.00017845831 | S22: =AB22/AB23-1 -> 0.00056179775 | T22: =AC22/AC23-1 -> 0.0071130566 | V22: =M22 -> 46153 | W22: =VLOOKUP($M22,LAST!$B:$Q,2,0) -> 213.53 | X22: =VLOOKUP($M22,LAST!$B:$Q,3,0)*100 -> 280.82 | Y22: =VLOOKUP($M22,LAST!$B:$Q,16,0)*100 -> 264 | Z22: =VLOOKUP($M22,LAST!$B:$Q,4,0) -> 95.41 | AA22: =VLOOKUP($M22,LAST!$B:$Q,5,0) -> 95.8378 | AB22: =VLOOKUP($M22,LAST!$B:$Q,6,0) -> 97.955 | AC22: =VLOOKUP($M22,LAST!$B:$Q,7,0) -> 1472.5
B23: =VLOOKUP(WORKDAY(DATE(YEAR($B$5)-10,MONTH($B$5),DAY($B$5)),0),$M:$M,1,0) -> 42524 | L23: =ROW(M23) -> 23 | M23: =WORKDAY(M22,-1) -> 46150 | N23: =W23/W24-1 -> 0.0081607909 | O23: =X23/X24-1 -> 0.0059123416 | P23: =Y23/Y24-1 -> 0.0075757576 | Q23: =Z23/Z24-1 -> -0.00010481082 | R23: =AA23/AA24-1 -> 0.00045104539 | S23: =AB23/AB24-1 -> -0.0017029174 | T23: =AC23/AC24-1 -> 0.0043965103 | V23: =M23 -> 46150 | W23: =VLOOKUP($M23,LAST!$B:$Q,2,0) -> 216.19 | X23: =VLOOKUP($M23,LAST!$B:$Q,3,0)*100 -> 284.13 | Y23: =VLOOKUP($M23,LAST!$B:$Q,16,0)*100 -> 266 | Z23: =VLOOKUP($M23,LAST!$B:$Q,4,0) -> 95.4 | AA23: =VLOOKUP($M23,LAST!$B:$Q,5,0) -> 95.8207 | AB23: =VLOOKUP($M23,LAST!$B:$Q,6,0) -> 97.9 | AC23: =VLOOKUP($M23,LAST!$B:$Q,7,0) -> 1462.1
B24: =INDEX($L:$L,MATCH(VLOOKUP(WORKDAY(DATE(YEAR($B$5)-10,MONTH($B$5),DAY($B$5)),0),$M:$M,1,0),M:M,0)) -> 2613 | L24: =ROW(M24) -> 24 | M24: =WORKDAY(M23,-1) -> 46149 | N24: =W24/W25-1 -> -0.0092862093 | O24: =X24/X25-1 -> -0.0017317547 | P24: =Y24/Y25-1 -> 0.0076335878 | Q24: =Z24/Z25-1 -> 0.00031453135 | R24: =AA24/AA25-1 -> 0.00037601249 | S24: =AB24/AB25-1 -> 0.00044887424 | T24: =AC24/AC25-1 -> 0.0054565548 | V24: =M24 -> 46149 | W24: =VLOOKUP($M24,LAST!$B:$Q,2,0) -> 214.44 | X24: =VLOOKUP($M24,LAST!$B:$Q,3,0)*100 -> 282.46 | Y24: =VLOOKUP($M24,LAST!$B:$Q,16,0)*100 -> 264 | Z24: =VLOOKUP($M24,LAST!$B:$Q,4,0) -> 95.41 | AA24: =VLOOKUP($M24,LAST!$B:$Q,5,0) -> 95.7775 | AB24: =VLOOKUP($M24,LAST!$B:$Q,6,0) -> 98.067 | AC24: =VLOOKUP($M24,LAST!$B:$Q,7,0) -> 1455.7
L25: =ROW(M25) -> 25 | M25: =WORKDAY(M24,-1) -> 46148 | N25: =W25/W26-1 -> -0.0099711842 | O25: =X25/X26-1 -> -0.011148389 | P25: =Y25/Y26-1 -> -0.015037594 | Q25: =Z25/Z26-1 -> 0.00073444549 | R25: =AA25/AA26-1 -> 2.611266e-05 | S25: =AB25/AB26-1 -> -0.004276543 | T25: =AC25/AC26-1 -> -0.017774763 | V25: =M25 -> 46148 | W25: =VLOOKUP($M25,LAST!$B:$Q,2,0) -> 216.45 | X25: =VLOOKUP($M25,LAST!$B:$Q,3,0)*100 -> 282.95 | Y25: =VLOOKUP($M25,LAST!$B:$Q,16,0)*100 -> 262 | Z25: =VLOOKUP($M25,LAST!$B:$Q,4,0) -> 95.38 | AA25: =VLOOKUP($M25,LAST!$B:$Q,5,0) -> 95.7415 | AB25: =VLOOKUP($M25,LAST!$B:$Q,6,0) -> 98.023 | AC25: =VLOOKUP($M25,LAST!$B:$Q,7,0) -> 1447.8
L26: =ROW(M26) -> 26 | M26: =WORKDAY(M25,-1) -> 46147 | N26: =W26/W27-1 -> -0.0061369215 | O26: =X26/X27-1 -> -0.00017470911 | P26: =Y26/Y27-1 -> -0.0037453184 | Q26: =Z26/Z27-1 -> 0 | R26: =AA26/AA27-1 -> 1.4623304e-05 | S26: =AB26/AB27-1 -> 0.00071157013 | T26: =AC26/AC27-1 -> 0 | V26: =M26 -> 46147 | W26: =VLOOKUP($M26,LAST!$B:$Q,2,0) -> 218.63 | X26: =VLOOKUP($M26,LAST!$B:$Q,3,0)*100 -> 286.14 | Y26: =VLOOKUP($M26,LAST!$B:$Q,16,0)*100 -> 266 | Z26: =VLOOKUP($M26,LAST!$B:$Q,4,0) -> 95.31 | AA26: =VLOOKUP($M26,LAST!$B:$Q,5,0) -> 95.739 | AB26: =VLOOKUP($M26,LAST!$B:$Q,6,0) -> 98.444 | AC26: =VLOOKUP($M26,LAST!$B:$Q,7,0) -> 1474
L27: =ROW(M27) -> 27 | M27: =WORKDAY(M26,-1) -> 46146 | N27: =W27/W28-1 -> -0.0064137308 | O27: =X27/X28-1 -> -0.0017092228 | P27: =Y27/Y28-1 -> 0.011363636 | Q27: =Z27/Z28-1 -> 0.00031486146 | R27: =AA27/AA28-1 -> -3.7601367e-05 | S27: =AB27/AB28-1 -> 0.0022209544 | T27: =AC27/AC28-1 -> -0.001929783 | V27: =M27 -> 46146 | W27: =VLOOKUP($M27,LAST!$B:$Q,2,0) -> 219.98 | X27: =VLOOKUP($M27,LAST!$B:$Q,3,0)*100 -> 286.19 | Y27: =VLOOKUP($M27,LAST!$B:$Q,16,0)*100 -> 267 | Z27: =VLOOKUP($M27,LAST!$B:$Q,4,0) -> 95.31 | AA27: =VLOOKUP($M27,LAST!$B:$Q,5,0) -> 95.7376 | AB27: =VLOOKUP($M27,LAST!$B:$Q,6,0) -> 98.374 | AC27: =VLOOKUP($M27,LAST!$B:$Q,7,0) -> 1474
L28: =ROW(M28) -> 28 | M28: =WORKDAY(M27,-1) -> 46143 | N28: =W28/W29-1 -> -0.016349742 | O28: =X28/X29-1 -> -0.0075469085 | P28: =Y28/Y29-1 -> -0.014925373 | Q28: =Z28/Z29-1 -> -0.00031476235 | R28: =AA28/AA29-1 -> -0.00016917753 | S28: =AB28/AB29-1 -> 0.0010198254 | T28: =AC28/AC29-1 -> 0 | V28: =M28 -> 46143 | W28: =VLOOKUP($M28,LAST!$B:$Q,2,0) -> 221.4 | X28: =VLOOKUP($M28,LAST!$B:$Q,3,0)*100 -> 286.68 | Y28: =VLOOKUP($M28,LAST!$B:$Q,16,0)*100 -> 264 | Z28: =VLOOKUP($M28,LAST!$B:$Q,4,0) -> 95.28 | AA28: =VLOOKUP($M28,LAST!$B:$Q,5,0) -> 95.7412 | AB28: =VLOOKUP($M28,LAST!$B:$Q,6,0) -> 98.156 | AC28: =VLOOKUP($M28,LAST!$B:$Q,7,0) -> 1476.85
L29: =ROW(M29) -> 29 | M29: =WORKDAY(M28,-1) -> 46142 | N29: =W29/W30-1 -> 0.014559387 | O29: =X29/X30-1 -> 0.0022553 | P29: =Y29/Y30-1 -> -0.0074074074 | Q29: =Z29/Z30-1 -> 0.00010493179 | R29: =AA29/AA30-1 -> 0.00014204575 | S29: =AB29/AB30-1 -> -0.0091450167 | T29: =AC29/AC30-1 -> -0.0079599651 | V29: =M29 -> 46142 | W29: =VLOOKUP($M29,LAST!$B:$Q,2,0) -> 225.08 | X29: =VLOOKUP($M29,LAST!$B:$Q,3,0)*100 -> 288.86 | Y29: =VLOOKUP($M29,LAST!$B:$Q,16,0)*100 -> 268 | Z29: =VLOOKUP($M29,LAST!$B:$Q,4,0) -> 95.31 | AA29: =VLOOKUP($M29,LAST!$B:$Q,5,0) -> 95.7574 | AB29: =VLOOKUP($M29,LAST!$B:$Q,6,0) -> 98.056 | AC29: =VLOOKUP($M29,LAST!$B:$Q,7,0) -> 1476.85
L30: =ROW(M30) -> 30 | M30: =WORKDAY(M29,-1) -> 46141 | N30: =W30/W31-1 -> -0.0233326 | O30: =X30/X31-1 -> -0.013756288 | P30: =Y30/Y31-1 -> -0.0036900369 | Q30: =Z30/Z31-1 -> 0 | R30: =AA30/AA31-1 -> 0.0004691799 | S30: =AB30/AB31-1 -> 0.0032542579 | T30: =AC30/AC31-1 -> 0.010761449 | V30: =M30 -> 46141 | W30: =VLOOKUP($M30,LAST!$B:$Q,2,0) -> 221.85 | X30: =VLOOKUP($M30,LAST!$B:$Q,3,0)*100 -> 288.21 | Y30: =VLOOKUP($M30,LAST!$B:$Q,16,0)*100 -> 270 | Z30: =VLOOKUP($M30,LAST!$B:$Q,4,0) -> 95.3 | AA30: =VLOOKUP($M30,LAST!$B:$Q,5,0) -> 95.7438 | AB30: =VLOOKUP($M30,LAST!$B:$Q,6,0) -> 98.961 | AC30: =VLOOKUP($M30,LAST!$B:$Q,7,0) -> 1488.7
L31: =ROW(M31) -> 31 | M31: =WORKDAY(M30,-1) -> 46140 | N31: =W31/W32-1 -> 0.013655228 | O31: =X31/X32-1 -> 0.0074117485 | P31: =Y31/Y32-1 -> 0.01119403 | Q31: =Z31/Z32-1 -> -0.00010492078 | R31: =AA31/AA32-1 -> 4.2844543e-05 | S31: =AB31/AB32-1 -> 0.0014619883 | T31: =AC31/AC32-1 -> -0.00091575092 | V31: =M31 -> 46140 | W31: =VLOOKUP($M31,LAST!$B:$Q,2,0) -> 227.15 | X31: =VLOOKUP($M31,LAST!$B:$Q,3,0)*100 -> 292.23 | Y31: =VLOOKUP($M31,LAST!$B:$Q,16,0)*100 -> 271 | Z31: =VLOOKUP($M31,LAST!$B:$Q,4,0) -> 95.3 | AA31: =VLOOKUP($M31,LAST!$B:$Q,5,0) -> 95.6989 | AB31: =VLOOKUP($M31,LAST!$B:$Q,6,0) -> 98.64 | AC31: =VLOOKUP($M31,LAST!$B:$Q,7,0) -> 1472.85
L32: =ROW(M32) -> 32 | M32: =WORKDAY(M31,-1) -> 46139 | N32: =W32/W33-1 -> -0.0009362461 | O32: =X32/X33-1 -> -0.0062009661 | P32: =Y32/Y33-1 -> -0.014705882 | Q32: =Z32/Z33-1 -> 0 | R32: =AA32/AA33-1 -> 0.00044745536 | S32: =AB32/AB33-1 -> -0.00037550871 | T32: =AC32/AC33-1 -> -0.0014224751 | V32: =M32 -> 46139 | W32: =VLOOKUP($M32,LAST!$B:$Q,2,0) -> 224.09 | X32: =VLOOKUP($M32,LAST!$B:$Q,3,0)*100 -> 290.08 | Y32: =VLOOKUP($M32,LAST!$B:$Q,16,0)*100 -> 268 | Z32: =VLOOKUP($M32,LAST!$B:$Q,4,0) -> 95.31 | AA32: =VLOOKUP($M32,LAST!$B:$Q,5,0) -> 95.6948 | AB32: =VLOOKUP($M32,LAST!$B:$Q,6,0) -> 98.496 | AC32: =VLOOKUP($M32,LAST!$B:$Q,7,0) -> 1474.2
L33: =ROW(M33) -> 33 | M33: =WORKDAY(M32,-1) -> 46136 | N33: =W33/W34-1 -> 0.017049061 | O33: =X33/X34-1 -> 0.0047156822 | P33: =Y33/Y34-1 -> 0 | Q33: =Z33/Z34-1 -> 0.00010493179 | R33: =AA33/AA34-1 -> 0.0010203601 | S33: =AB33/AB34-1 -> -0.002399514 | T33: =AC33/AC34-1 -> -0.0015217612 | V33: =M33 -> 46136 | W33: =VLOOKUP($M33,LAST!$B:$Q,2,0) -> 224.3 | X33: =VLOOKUP($M33,LAST!$B:$Q,3,0)*100 -> 291.89 | Y33: =VLOOKUP($M33,LAST!$B:$Q,16,0)*100 -> 272 | Z33: =VLOOKUP($M33,LAST!$B:$Q,4,0) -> 95.31 | AA33: =VLOOKUP($M33,LAST!$B:$Q,5,0) -> 95.652 | AB33: =VLOOKUP($M33,LAST!$B:$Q,6,0) -> 98.533 | AC33: =VLOOKUP($M33,LAST!$B:$Q,7,0) -> 1476.3
L34: =ROW(M34) -> 34 | M34: =WORKDAY(M33,-1) -> 46135 | N34: =W34/W35-1 -> 0.0085055789 | O34: =X34/X35-1 -> 0.0085398875 | P34: =Y34/Y35-1 -> 0.011152416 | Q34: =Z34/Z35-1 -> 0.00010494281 | R34: =AA34/AA35-1 -> 0.0012605544 | S34: =AB34/AB35-1 -> 0.001825743 | T34: =AC34/AC35-1 -> 0.00013528596 | V34: =M34 -> 46135 | W34: =VLOOKUP($M34,LAST!$B:$Q,2,0) -> 220.54 | X34: =VLOOKUP($M34,LAST!$B:$Q,3,0)*100 -> 290.52 | Y34: =VLOOKUP($M34,LAST!$B:$Q,16,0)*100 -> 272 | Z34: =VLOOKUP($M34,LAST!$B:$Q,4,0) -> 95.3 | AA34: =VLOOKUP($M34,LAST!$B:$Q,5,0) -> 95.5545 | AB34: =VLOOKUP($M34,LAST!$B:$Q,6,0) -> 98.77 | AC34: =VLOOKUP($M34,LAST!$B:$Q,7,0) -> 1478.55
L35: =ROW(M35) -> 35 | M35: =WORKDAY(M34,-1) -> 46134 | N35: =W35/W36-1 -> -0.0025542784 | O35: =X35/X36-1 -> -0.00048577377 | P35: =Y35/Y36-1 -> 0 | Q35: =Z35/Z36-1 -> 0.00041994751 | R35: =AA35/AA36-1 -> 0.00071199155 | S35: =AB35/AB36-1 -> 0.0019919914 | T35: =AC35/AC36-1 -> -0.0014522121 | V35: =M35 -> 46134 | W35: =VLOOKUP($M35,LAST!$B:$Q,2,0) -> 218.68 | X35: =VLOOKUP($M35,LAST!$B:$Q,3,0)*100 -> 288.06 | Y35: =VLOOKUP($M35,LAST!$B:$Q,16,0)*100 -> 269 | Z35: =VLOOKUP($M35,LAST!$B:$Q,4,0) -> 95.29 | AA35: =VLOOKUP($M35,LAST!$B:$Q,5,0) -> 95.4342 | AB35: =VLOOKUP($M35,LAST!$B:$Q,6,0) -> 98.59 | AC35: =VLOOKUP($M35,LAST!$B:$Q,7,0) -> 1478.35
L36: =ROW(M36) -> 36 | M36: =WORKDAY(M35,-1) -> 46133 | N36: =W36/W37-1 -> -0.0103372 | O36: =X36/X37-1 -> -0.0094517958 | P36: =Y36/Y37-1 -> -0.0037037037 | Q36: =Z36/Z37-1 -> 0.00063031831 | R36: =AA36/AA37-1 -> 0.00092781222 | S36: =AB36/AB37-1 -> 0.0030276155 | T36: =AC36/AC37-1 -> 0.0054329372 | V36: =M36 -> 46133 | W36: =VLOOKUP($M36,LAST!$B:$Q,2,0) -> 219.24 | X36: =VLOOKUP($M36,LAST!$B:$Q,3,0)*100 -> 288.2 | Y36: =VLOOKUP($M36,LAST!$B:$Q,16,0)*100 -> 269 | Z36: =VLOOKUP($M36,LAST!$B:$Q,4,0) -> 95.25 | AA36: =VLOOKUP($M36,LAST!$B:$Q,5,0) -> 95.3663 | AB36: =VLOOKUP($M36,LAST!$B:$Q,6,0) -> 98.394 | AC36: =VLOOKUP($M36,LAST!$B:$Q,7,0) -> 1480.5
... L2690: =ROW(M2690) -> 2690 | M2690: =WORKDAY(M2689,-1) -> 42417 | N2690: =W2690/W2691-1 -> -0.028970913 | O2690: =X2690/X2691-1 -> -0.024236808 | P2690: =Y2690/Y2691-1 -> -0.029776675 | Q2690: =Z2690/Z2691-1 -> -0.00033598387 | R2690: =AA2690/AA2691-1 -> -0.0010898491 | S2690: =AB2690/AB2691-1 -> -0.00084651278 | T2690: =AC2690/AC2691-1 -> 0.0087950025 | V2690: =M2690 -> 42417 | W2690: =VLOOKUP($M2690,LAST!$B:$Q,2,0) -> 501.42 | X2690: =VLOOKUP($M2690,LAST!$B:$Q,3,0)*100 -> 747.62 | Y2690: =VLOOKUP($M2690,LAST!$B:$Q,16,0)*100 -> 782 | Z2690: =VLOOKUP($M2690,LAST!$B:$Q,4,0) -> 89.26 | AA2690: =VLOOKUP($M2690,LAST!$B:$Q,5,0) -> 95.2304 | AB2690: =VLOOKUP($M2690,LAST!$B:$Q,6,0) -> 96.786 | AC2690: =VLOOKUP($M2690,LAST!$B:$Q,7,0) -> 1227.3
L2691: =ROW(M2691) -> 2691 | M2691: =WORKDAY(M2690,-1) -> 42416 | V2691: =M2691 -> 42416 | W2691: =VLOOKUP($M2691,LAST!$B:$Q,2,0) -> 516.38 | X2691: =VLOOKUP($M2691,LAST!$B:$Q,3,0)*100 -> 766.19 | Y2691: =VLOOKUP($M2691,LAST!$B:$Q,16,0)*100 -> 806 | Z2691: =VLOOKUP($M2691,LAST!$B:$Q,4,0) -> 89.29 | AA2691: =VLOOKUP($M2691,LAST!$B:$Q,5,0) -> 95.3343 | AB2691: =VLOOKUP($M2691,LAST!$B:$Q,6,0) -> 96.868 | AC2691: =VLOOKUP($M2691,LAST!$B:$Q,7,0) -> 1216.6

Sheet LAST
B2: 시작일 | C2: 41275
B3: 종료일
C5: JPEIGLSP Index | D5: LG30OAS INDEX | E5: SPBDALB Index | F5: SPBDELB Index | G5: DXY Curncy | H5: KRW REGN Curncy | I5: EUR BGN Curncy | J5: CNY CURNCY | K5: BRLKRW INDEX | L5: BTC1 Curncy | M5: CLA COMDTY | N5: XAU CURNCY | O5: NG1 COMB Comdty | P5: JKL1 COMB Comdty | Q5: LF98OAS Index | R5: LUACOAS Index | S5: LD07OAS Index | T5: BTXMOAS Index | U5: BDIY Index | V5: SPX Index | W5: CCMP Index | X5: HSCEI Index | Y5: KOSPI Index | Z5: NKY Index
C6: =_xll.BFieldInfo(C$7) -> Last Price | D6: =_xll.BFieldInfo(D$7) -> Last Price | E6: =_xll.BFieldInfo(E$7) -> Last Price | F6: =_xll.BFieldInfo(F$7) -> Last Price | G6: =_xll.BFieldInfo(G$7) -> Last Price | H6: =_xll.BFieldInfo(H$7) -> Last Price | I6: =_xll.BFieldInfo(I$7) -> Last Price | J6: =_xll.BFieldInfo(J$7) -> Last Price | ... Z6: =_xll.BFieldInfo(Z$7) -> Last Price
B7: Dates | C7: PX_LAST | D7: PX_LAST | E7: PX_LAST | F7: PX_LAST | G7: PX_LAST | H7: PX_LAST | I7: PX_LAST | J7: PX_LAST | K7: PX_LAST | L7: PX_LAST | M7: PX_LAST | N7: PX_LAST | O7: PX_LAST | P7: PX_LAST | Q7: PX_LAST | R7: PX_LAST | S7: PX_LAST | T7: PX_LAST | U7: PX_LAST | V7: PX_LAST | W7: PX_LAST | X7: PX_LAST | Y7: PX_LAST | Z7: PX_LAST
B8: {=_xll.BDH(C$5,C$7,$C2,$C3,"Dir=V","CDR=7D","Days=A","Dts=S","Sort=R")} -> 46177 | C8: 215.27 | D8: {=_xll.BDH(D$5,D$7,$C2,$C3,"Dir=V","CDR=7D","Days=A","Dts=H","Sort=R")} -> 2.754 | E8: {=_xll.BDH(E$5,E$7,$C2,$C3,"Dir=V","CDR=7D","Days=A","Dts=H","Sort=R")} -> 95.33 | F8: {=_xll.BDH(F$5,F$7,$C2,$C3,"Dir=V","CDR=7D","Days=A","Dts=H","Sort=R")} -> 96.1871 | G8: {=_xll.BDH(G$5,G$7,$C2,$C3,"Dir=V","CDR=7D","Days=A","Dts=H","Sort=R")} -> 99.529 | H8: {=_xll.BDH(H$5,H$7,$C2,$C3,"Dir=V","CDR=7D","Days=A","Dts=H","Sort=R")} -> 1518.95 | I8: {=_xll.BDH(I$5,I$7,$C2,$C3,"Dir=V","CDR=7D","Days=A","Dts=H","Sort=R")} -> 1.1607 | J8: {=_xll.BDH(J$5,J$7,$C2,$C3,"Dir=V","CDR=7D","Days=A","Dts=H","Sort=R")} -> 6.7785 | K8: {=_xll.BDH(K$5,K$7,$C2,$C3,"Dir=V","CDR=7D","Days=A","Dts=H","Sort=R")} -> 303.1158 | ... Z8: {=_xll.BDH(Z$5,Z$7,$C2,$C3,"Dir=V","CDR=7D","Days=A","Dts=H","Sort=R")} -> 68402.13
B9: 46176 | C9: 215.27 | D9: 2.754 | E9: 95.33 | F9: 96.1871 | G9: 99.529 | H9: 1518.95 | I9: 1.1597 | J9: 6.7785 | K9: 303.0253 | L9: 65585 | M9: 96.02 | N9: 4434.81 | O9: 3.214 | P9: 18.815 | Q9: 2.63 | R9: 0.73 | S9: 0.88 | T9: 0.67 | U9: 3205 | V9: 7553.68 | W9: 26853.97 | X9: 8596.59 | Y9: 8801.49 | Z9: 68402.13
B10: 46175 | C10: 214.92 | D10: 2.7333 | E10: 95.33 | F10: 96.1899 | G10: 99.219 | H10: 1518.95 | I10: 1.1631 | J10: 6.7638 | K10: 303.2977 | L10: 67395 | M10: 93.76 | N10: 4488.86 | O10: 3.167 | P10: 18.61 | Q10: 2.57 | R10: 0.72 | S10: 0.87 | T10: 0.67 | U10: 3205 | V10: 7609.78 | W10: 27093.9 | X10: 8762.97 | Y10: 8801.49 | Z10: 66734.24
B11: 46174 | C11: 218.75 | D11: 2.7539 | E11: 95.34 | F11: 96.1751 | G11: 99.201 | H11: 1513.05 | I11: 1.1631 | J11: 6.767 | K11: 300.9313 | L11: 71735 | M11: 92.16 | N11: 4484.98 | O11: 3.179 | P11: 18.685 | Q11: 2.59 | R11: 0.72 | S11: 0.87 | T11: 0.68 | U11: 3222 | V11: 7599.96 | W11: 27086.81 | X11: 8507.87 | Y11: 8788.38 | Z11: 66934.33
B12: 46173 | C12: 214.56 | D12: 2.7742 | E12: 95.33 | F12: 96.1439 | G12: 98.942 | H12: 1503.95 | I12: 1.1659 | J12: 6.7663 | K12: 298.7618 | L12: 72766.96 | M12: 87.36 | N12: 4540.26 | O12: 3.29 | P12: 18.3 | Q12: 2.57 | R12: 0.72 | S12: 0.87 | T12: 0.69 | U12: 3224 | V12: 7580.06 | W12: 26972.62 | X12: 8425.82 | Y12: 8476.15 | Z12: 66329.5
B13: 46172 | C13: 214.56 | D13: 2.7742 | E13: 95.33 | F13: 96.1439 | G13: 98.942 | H13: 1503.95 | I13: 1.1659 | J13: 6.7663 | K13: 298.7618 | L13: 72766.96 | M13: 87.36 | N13: 4540.26 | O13: 3.29 | P13: 18.3 | Q13: 2.57 | R13: 0.72 | S13: 0.87 | T13: 0.69 | U13: 3224 | V13: 7580.06 | W13: 26972.62 | X13: 8425.82 | Y13: 8476.15 | Z13: 66329.5
B14: 46171 | C14: 214.56 | D14: 2.7742 | E14: 95.32 | F14: 96.1439 | G14: 98.942 | H14: 1503.95 | I14: 1.1659 | J14: 6.7663 | K14: 298.7618 | L14: 72766.96 | M14: 87.36 | N14: 4540.26 | O14: 3.29 | P14: 18.3 | Q14: 2.57 | R14: 0.72 | S14: 0.87 | T14: 0.69 | U14: 3224 | V14: 7580.06 | W14: 26972.62 | X14: 8425.82 | Y14: 8476.15 | Z14: 66329.5
B15: 46170 | C15: 217.99 | D15: 2.8102 | E15: 95.25 | F15: 96.167 | G15: 99.02 | H15: 1494.2 | I15: 1.1651 | J15: 6.7757 | K15: 296.3284 | L15: 73355 | M15: 88.9 | N15: 4495.29 | O15: 3.285 | P15: 18.335 | Q15: 2.61 | R15: 0.72 | S15: 0.88 | T15: 0.68 | U15: 3226 | V15: 7563.63 | W15: 26917.47 | X15: 8364.41 | Y15: 8185.29 | Z15: 64693.12
B16: 46169 | C16: 218.48 | D16: 2.8145 | E16: 95.26 | F16: 96.1781 | G16: 99.206 | H16: 1499.45 | I16: 1.1626 | J16: 6.7792 | K16: 296.4857 | L16: 74905 | M16: 88.68 | N16: 4453.98 | O16: 3.04 | P16: 18.235 | Q16: 2.61 | R16: 0.73 | S16: 0.89 | T16: 0.68 | U16: 3124 | V16: 7520.36 | W16: 26674.73 | X16: 8463.02 | Y16: 8228.7 | Z16: 64999.41
B17: 46168 | C17: 221.83 | D17: 2.8342 | E17: 95.27 | F17: 96.1903 | G17: 99.169 | H17: 1507.55 | I17: 1.1631 | J17: 6.7861 | K17: 299.5839 | L17: 75895 | M17: 93.89 | N17: 4507.88 | O17: 2.894 | P17: 18.425 | Q17: 2.61 | R17: 0.73 | S17: 0.89 | T17: 0.68 | U17: 3085 | V17: 7519.12 | W17: 26656.18 | X17: 8576.89 | Y17: 8047.51 | Z17: 64996.09
B18: 46167 | C18: 220.81 | D18: 2.8326 | E18: 95.25 | F18: 96.1944 | G18: 99.239 | H18: 1517.55 | I18: 1.1644 | J18: 6.7832 | K18: 301.2925 | L18: 75775 | M18: 96.6 | N18: 4570.5 | O18: 2.907 | P18: 18.81 | Q18: 2.6 | R18: 0.72 | S18: 0.88 | T18: 0.68 | U18: 2991 | V18: 7473.47 | W18: 26343.97 | X18: 8550.87 | Y18: 7847.71 | Z18: 65158.19
B19: 46166 | C19: 220.81 | D19: 2.8253 | E19: 95.25 | F19: 96.1871 | G19: 99.239 | H19: 1517.55 | I19: 1.1603 | J19: 6.7963 | K19: 301.3115 | L19: 75775 | M19: 96.6 | N19: 4509.4 | O19: 2.907 | P19: 18.81 | Q19: 2.6 | R19: 0.72 | S19: 0.88 | T19: 0.68 | U19: 2991 | V19: 7473.47 | W19: 26343.97 | X19: 8550.87 | Y19: 7847.71 | Z19: 63339.07
B20: 46165 | C20: 220.81 | D20: 2.8253 | E20: 95.25 | F20: 96.1871 | G20: 99.239 | H20: 1517.55 | I20: 1.1603 | J20: 6.7963 | K20: 301.3115 | L20: 75775 | M20: 96.6 | N20: 4509.4 | O20: 2.907 | P20: 18.81 | Q20: 2.6 | R20: 0.72 | S20: 0.88 | T20: 0.68 | U20: 2991 | V20: 7473.47 | W20: 26343.97 | X20: 8550.87 | Y20: 7847.71 | Z20: 63339.07
... B3066: 43119 | C3066: 297.29 | D3066: 3.1685 | E3066: 98.44 | F3066: 99.4929 | G3066: 90.572 | H3066: 1065.9 | I3066: 1.2222 | J3066: 6.404 | K3066: 334.1147 | L3066: 11360 | M3066: 54.51 | N3066: 1331.84 | O3066: 3.185 | P3066: 10.545 | Q3066: 3.19 | R3066: 0.9 | S3066: 1.31 | T3066: 1.12 | U3066: 1125 | V3066: 2810.3 | W3066: 7336.38 | X3066: 13179.52 | Y3066: 2520.26 | Z3066: 23808.06
B3067: 43118 | C3067: 295.01 | D3067: 3.161 | E3067: 98.4 | F3067: 99.4655 | G3067: 90.498 | H3067: 1070.5 | I3067: 1.2238 | J3067: 6.42 | K3067: 333.923 | L3067: 11815 | M3067: #N/A N/A | N3067: 1327.03 | O3067: 3.189 | P3067: 10.545 | Q3067: 3.2 | R3067: 0.89 | S3067: 1.31 | T3067: 1.13 | U3067: 1139 | V3067: 2798.03 | W3067: 7296.05 | X3067: 13094.92 | Y3067: 2515.81 | Z3067: 23763.37
B3068: 43117 | C3068: 295.9 | D3068: 3.1519 | E3068: 98.36 | F3068: 99.4506 | G3068: 90.541 | H3068: 1069.25 | I3068: 1.2186 | J3068: 6.4343 | K3068: 331.0931 | L3068: 10945 | M3068: #N/A N/A | N3068: 1326.84 | O3068: 3.232 | P3068: 10.5 | Q3068: 3.18 | R3068: 0.89 | S3068: 1.31 | T3068: 1.14 | U3068: 1164 | V3068: 2802.56 | W3068: 7298.28 | X3068: 12868.78 | Y3068: 2515.43 | Z3068: 23868.34
B3069: 43116 | C3069: 297.76 | D3069: 3.1731 | E3069: 98.34 | F3069: 99.4435 | G3069: 90.393 | H3069: 1062.65 | I3069: 1.226 | J3069: 6.444 | K3069: 329.9694 | L3069: 11160 | M3069: #N/A N/A | N3069: 1338.41 | O3069: 3.129 | P3069: 10.45 | Q3069: 3.21 | R3069: 0.89 | S3069: 1.3 | T3069: 1.14 | U3069: 1221 | V3069: 2776.42 | W3069: 7223.69 | X3069: 12787.28 | Y3069: 2521.74 | Z3069: 23951.81
B3070: 43115 | C3070: 299.81 | D3070: 3.192 | E3070: 98.33 | F3070: 99.4309 | G3070: 90.974 | H3070: 1062.7 | I3070: 1.2264 | J3070: 6.4371 | K3070: 330.6472 | L3070: 13945 | M3070: #N/A N/A | N3070: 1339.99 | O3070: 3.2 | P3070: 11.23 | Q3070: 3.23 | R3070: 0.9 | S3070: 1.31 | T3070: 1.14 | U3070: 1264 | V3070: 2786.24 | W3070: 7261.06 | X3070: 12470.42 | Y3070: 2503.73 | Z3070: 23714.88
B3071: 43114 | C3071: 299.81 | D3071: 3.2002 | E3071: 98.33 | F3071: 99.4483 | G3071: 90.974 | H3071: 1064.9 | I3071: 1.2202 | J3071: 6.469 | K3071: 330.6341 | L3071: 13945 | M3071: #N/A N/A | N3071: 1337.64 | O3071: 3.2 | P3071: 11.23 | Q3071: 3.23 | R3071: 0.9 | S3071: 1.31 | T3071: 1.14 | U3071: 1279 | V3071: 2786.24 | W3071: 7261.06 | X3071: 12468.93 | Y3071: 2496.42 | Z3071: 23653.82
B3072: 43113 | C3072: 299.81 | D3072: 3.2002 | E3072: 98.33 | F3072: 99.4483 | G3072: 90.974 | H3072: 1064.9 | I3072: 1.2202 | J3072: 6.469 | K3072: 330.6341 | L3072: 13945 | M3072: #N/A N/A | N3072: 1337.64 | O3072: 3.2 | P3072: 11.23 | Q3072: 3.23 | R3072: 0.9 | S3072: 1.31 | T3072: 1.14 | U3072: 1279 | V3072: 2786.24 | W3072: 7261.06 | X3072: 12468.93 | Y3072: 2496.42 | Z3072: 23653.82
B3073: 43112 | C3073: 299.81 | D3073: 3.2002 | E3073: 98.33 | F3073: 99.4483 | G3073: 90.974 | H3073: 1064.9 | I3073: 1.2202 | J3073: 6.469 | K3073: 330.6341 | L3073: 13945 | M3073: #N/A N/A | N3073: 1337.64 | O3073: 3.2 | P3073: 11.23 | Q3073: 3.23 | R3073: 0.9 | S3073: 1.31 | T3073: 1.14 | U3073: 1279 | V3073: 2786.24 | W3073: 7261.06 | X3073: 12468.93 | Y3073: 2496.42 | Z3073: 23653.82
B3074: 43111 | C3074: 301.83 | D3074: 3.2115 | E3074: 98.31 | F3074: 99.4663 | G3074: 91.852 | H3074: 1072.1 | I3074: 1.2032 | J3074: 6.5063 | K3074: 331.5157 | L3074: 13385 | M3074: #N/A N/A | N3074: 1322.44 | O3074: 3.084 | P3074: 11.215 | Q3074: 3.24 | R3074: 0.9 | S3074: 1.31 | T3074: 1.15 | U3074: 1303 | V3074: 2767.56 | W3074: 7211.78 | X3074: 12295.52 | Y3074: 2487.91 | Z3074: 23710.43
B3075: 43110 | C3075: 301.83 | D3075: 3.2206 | E3075: 98.3 | F3075: 99.5212 | G3075: 92.332 | H3075: 1071.85 | I3075: 1.1948 | J3075: 6.5082 | K3075: 331.5008 | L3075: 14450 | M3075: #N/A N/A | N3075: 1316.89 | O3075: 2.906 | P3075: 11.185 | Q3075: 3.25 | R3075: 0.9 | S3075: 1.32 | T3075: 1.16 | U3075: 1366 | V3075: 2748.23 | W3075: 7153.57 | X3075: 12289.17 | Y3075: 2499.75 | Z3075: 23788.2
B3076: 43109 | C3076: 297.63 | D3076: 3.1729 | E3076: 98.27 | F3076: 99.4945 | G3076: 92.528 | H3076: 1067.1 | I3076: 1.1937 | J3076: 6.5297 | K3076: 330.0321 | L3076: 14750 | M3076: #N/A N/A | N3076: 1312.85 | O3076: 2.923 | P3076: 11.18 | Q3076: 3.18 | R3076: 0.91 | S3076: 1.34 | T3076: 1.16 | U3076: 1395 | V3076: 2751.29 | W3076: 7163.58 | X3076: 12255.68 | Y3076: 2510.23 | Z3076: 23849.99
B3077: 43108 | C3077: 301.03 | D3077: 3.1747 | E3077: 98.25 | F3077: 99.5014 | G3077: 92.358 | H3077: 1066.1 | I3077: 1.1967 | J3077: 6.4998 | K3077: 330.2008 | L3077: 14905 | M3077: #N/A N/A | N3077: 1320.4 | O3077: 2.835 | P3077: 11.17 | Q3077: 3.2 | R3077: 0.92 | S3077: 1.36 | T3077: 1.16 | U3077: 1385 | V3077: 2747.71 | W3077: 7157.39 | X3077: 12235.19 | Y3077: 2513.28 | Z3077: 23714.53
B3078: 43107 | C3078: 300.42 | D3078: 3.2008 | E3078: 98.23 | F3078: 99.5198 | G3078: 91.949 | H3078: 1062.75 | I3078: 1.2029 | J3078: 6.4884 | K3078: 328.9703 | L3078: 16590 | M3078: #N/A N/A | N3078: 1319.59 | O3078: 2.795 | P3078: 11.17 | Q3078: 3.22 | R3078: 0.93 | S3078: 1.37 | T3078: 1.16 | U3078: 1371 | V3078: 2743.15 | W3078: 7136.56 | X3078: 12211.63 | Y3078: 2497.52 | Z3078: 23714.53
... B3101: 43084 | C3101: 315.19 | D3101: 3.5057 | E3101: 97.95 | F3101: 99.439 | G3101: 93.932 | H3101: 1089.38 | I3101: 1.1749 | J3101: 6.6093 | K3101: 330.6063 | L3101: 19500 | M3101: #N/A N/A | N3101: 1256.44 | O3101: 2.612 | P3101: 9.965 | Q3101: 3.5 | R3101: 0.95 | S3101: 1.39 | T3101: 1.16 | U3101: 1619 | V3101: 2675.81 | W3101: 6936.58 | X3101: 11365.92 | Y3101: 2482.07 | Z3101: 22553.22
B3102: 43083 | C3102: 316.89 | D3102: 3.5187 | E3102: 97.95 | F3102: 99.4688 | G3102: 93.489 | H3102: 1088.95 | I3102: 1.1778 | J3102: 6.6093 | K3102: 325.8433 | L3102: #N/A N/A | M3102: #N/A N/A | N3102: 1252.96 | O3102: 2.684 | P3102: 9.96 | Q3102: 3.5 | R3102: 0.95 | S3102: 1.4 | T3102: 1.16 | U3102: 1668 | V3102: 2652.01 | W3102: 6856.53 | X3102: 11531.73 | Y3102: 2469.48 | Z3102: 22694.45
B3103: 43082 | C3103: 317.27 | D3103: 3.5158 | E3103: 97.97 | F3103: 99.4829 | G3103: 93.429 | H3103: 1090.65 | I3103: 1.1826 | J3103: 6.6195 | K3103: 327.6678 | L3103: #N/A N/A | M3103: #N/A N/A | N3103: 1255.5 | O3103: 2.715 | P3103: 9.93 | Q3103: 3.5 | R3103: 0.96 | S3103: 1.41 | T3103: 1.16 | U3103: 1730 | V3103: 2662.85 | W3103: 6875.8 | X3103: 11519.79 | Y3103: 2480.55 | Z3103: 22758.07
B3104: 43081 | C3104: 314.35 | D3104: 3.475 | E3104: 98.02 | F3104: 99.483 | G3104: 94.101 | H3104: 1092.3 | I3104: 1.1742 | J3104: 6.6215 | K3104: 330.4479 | L3104: #N/A N/A | M3104: #N/A N/A | N3104: 1244.49 | O3104: 2.678 | P3104: 9.915 | Q3104: 3.44 | R3104: 0.96 | S3104: 1.41 | T3104: 1.16 | U3104: 1743 | V3104: 2664.11 | W3104: 6862.32 | X3104: 11312.57 | Y3104: 2461 | Z3104: 22866.17
B3105: 43080 | C3105: 315.15 | D3105: 3.4918 | E3105: 98.01 | F3105: 99.5054 | G3105: 93.866 | H3105: 1092.2 | I3105: 1.1769 | J3105: 6.6186 | K3105: 329.602 | L3105: #N/A N/A | M3105: #N/A N/A | N3105: 1242.02 | O3105: 2.828 | P3105: 9.9 | Q3105: 3.47 | R3105: 0.96 | S3105: 1.42 | T3105: 1.16 | U3105: 1727 | V3105: 2659.99 | W3105: 6875.08 | X3105: 11431.62 | Y3105: 2471.49 | Z3105: 22938.73
B3106: 43079 | C3106: 315.73 | D3106: 3.4981 | E3106: 98.01 | F3106: 99.5496 | G3106: 93.901 | H3106: 1093.5 | I3106: 1.1773 | J3106: 6.6209 | K3106: 331.9615 | L3106: #N/A N/A | M3106: #N/A N/A | N3106: 1248.49 | O3106: 2.772 | P3106: 9.89 | Q3106: 3.47 | R3106: 0.97 | S3106: 1.42 | T3106: 1.16 | U3106: 1702 | V3106: 2651.5 | W3106: 6840.08 | X3106: 11289.57 | Y3106: 2464 | Z3106: 22811.08
B3107: 43078 | C3107: 315.73 | D3107: 3.4981 | E3107: 98.01 | F3107: 99.5496 | G3107: 93.901 | H3107: 1093.5 | I3107: 1.1773 | J3107: 6.6209 | K3107: 331.9615 | L3107: #N/A N/A | M3107: #N/A N/A | N3107: 1248.49 | O3107: 2.772 | P3107: 9.89 | Q3107: 3.47 | R3107: 0.97 | S3107: 1.42 | T3107: 1.16 | U3107: 1702 | V3107: 2651.5 | W3107: 6840.08 | X3107: 11289.57 | Y3107: 2464 | Z3107: 22811.08
B3108: 43077 | C3108: 315.73 | D3108: 3.4981 | E3108: 98 | F3108: 99.5496 | G3108: 93.901 | H3108: 1093.5 | I3108: 1.1773 | J3108: 6.6209 | K3108: 331.9615 | L3108: #N/A N/A | M3108: #N/A N/A | N3108: 1248.49 | O3108: 2.772 | P3108: 9.89 | Q3108: 3.47 | R3108: 0.97 | S3108: 1.42 | T3108: 1.16 | U3108: 1702 | V3108: 2651.5 | W3108: 6840.08 | X3108: 11289.57 | Y3108: 2464 | Z3108: 22811.08
B3109: 43076 | C3109: 315.61 | D3109: 3.4825 | E3109: 98 | F3109: 99.5842 | G3109: 93.795 | H3109: 1093.45 | I3109: 1.1773 | J3109: 6.6193 | K3109: 332.341 | L3109: #N/A N/A | M3109: #N/A N/A | N3109: 1247.22 | O3109: 2.763 | P3109: 9.89 | Q3109: 3.47 | R3109: 0.97 | S3109: 1.42 | T3109: 1.16 | U3109: 1679 | V3109: 2636.98 | W3109: 6812.84 | X3109: 11150.73 | Y3109: 2461.98 | Z3109: 22498.03
...
